2025-04-27 13:04:01,739 - ftms - ERROR - Error discovering devices: 'FTMSDeviceSimulator' object has no attribute 'discover_devices'
2025-04-27 13:04:01,950 - ftms - ERROR - Error discovering devices: 'FTMSDeviceSimulator' object has no attribute 'discover_devices'
2025-04-27 13:04:06,742 - ftms - ERROR - Error discovering devices: 'FTMSDeviceSimulator' object has no attribute 'discover_devices'
2025-04-27 13:04:06,953 - ftms - ERROR - Error discovering devices: 'FTMSDeviceSimulator' object has no attribute 'discover_devices'
2025-04-27 13:04:11,743 - ftms - ERROR - Error discovering devices: 'FTMSDeviceSimulator' object has no attribute 'discover_devices'
2025-04-27 13:04:11,954 - ftms - ERROR - Error discovering devices: 'FTMSDeviceSimulator' object has no attribute 'discover_devices'
2025-04-27 13:04:13,181 - ftms - ERROR - Error discovering devices: 'FTMSDeviceSimulator' object has no attribute 'discover_devices'
2025-04-27 13:04:16,748 - ftms - ERROR - Error discovering devices: 'FTMSDeviceSimulator' object has no attribute 'discover_devices'
2025-04-27 13:04:16,959 - ftms - ERROR - Error discovering devices: 'FTMSDeviceSimulator' object has no attribute 'discover_devices'
2025-04-27 13:04:21,749 - ftms - ERROR - Error discovering devices: 'FTMSDeviceSimulator' object has no attribute 'discover_devices'
2025-04-27 13:04:21,959 - ftms - ERROR - Error discovering devices: 'FTMSDeviceSimulator' object has no attribute 'discover_devices'
2025-04-27 13:04:26,750 - ftms - ERROR - Error discovering devices: 'FTMSDeviceSimulator' object has no attribute 'discover_devices'
2025-04-27 13:04:26,962 - ftms - ERROR - Error discovering devices: 'FTMSDeviceSimulator' object has no attribute 'discover_devices'
2025-04-27 13:04:31,751 - ftms - ERROR - Error discovering devices: 'FTMSDeviceSimulator' object has no attribute 'discover_devices'
2025-04-27 13:04:31,963 - ftms - ERROR - Error discovering devices: 'FTMSDeviceSimulator' object has no attribute 'discover_devices'
2025-04-27 13:04:36,752 - ftms - ERROR - Error discovering devices: 'FTMSDeviceSimulator' object has no attribute 'discover_devices'
2025-04-27 13:04:36,964 - ftms - ERROR - Error discovering devices: 'FTMSDeviceSimulator' object has no attribute 'discover_devices'
2025-04-27 13:04:41,753 - ftms - ERROR - Error discovering devices: 'FTMSDeviceSimulator' object has no attribute 'discover_devices'
2025-04-27 13:04:41,965 - ftms - ERROR - Error discovering devices: 'FTMSDeviceSimulator' object has no attribute 'discover_devices'
2025-04-27 13:04:43,857 - ftms - ERROR - Error discovering devices: 'FTMSDeviceSimulator' object has no attribute 'discover_devices'
2025-04-27 13:04:46,754 - ftms - ERROR - Error discovering devices: 'FTMSDeviceSimulator' object has no attribute 'discover_devices'
2025-04-27 13:06:34,626 - ftms - ERROR - Error discovering devices: 'FTMSDeviceSimulator' object has no attribute 'discover_devices'
2025-04-27 13:06:34,833 - ftms - ERROR - Error discovering devices: 'FTMSDeviceSimulator' object has no attribute 'discover_devices'
2025-04-27 13:06:39,627 - ftms - ERROR - Error discovering devices: 'FTMSDeviceSimulator' object has no attribute 'discover_devices'
2025-04-27 13:06:39,836 - ftms - ERROR - Error discovering devices: 'FTMSDeviceSimulator' object has no attribute 'discover_devices'
2025-04-27 13:06:43,780 - ftms - ERROR - Error discovering devices: 'FTMSDeviceSimulator' object has no attribute 'discover_devices'
2025-04-27 13:06:44,628 - ftms - ERROR - Error discovering devices: 'FTMSDeviceSimulator' object has no attribute 'discover_devices'
2025-04-27 13:06:44,838 - ftms - ERROR - Error discovering devices: 'FTMSDeviceSimulator' object has no attribute 'discover_devices'
2025-04-27 13:06:48,072 - ftms - ERROR - Error discovering devices: 'FTMSDeviceSimulator' object has no attribute 'discover_devices'
2025-04-27 13:06:49,629 - ftms - ERROR - Error discovering devices: 'FTMSDeviceSimulator' object has no attribute 'discover_devices'
2025-04-27 13:06:49,839 - ftms - ERROR - Error discovering devices: 'FTMSDeviceSimulator' object has no attribute 'discover_devices'
2025-04-27 13:06:50,390 - ftms - ERROR - Error discovering devices: 'FTMSDeviceSimulator' object has no attribute 'discover_devices'
2025-04-27 13:06:54,630 - ftms - ERROR - Error discovering devices: 'FTMSDeviceSimulator' object has no attribute 'discover_devices'
2025-04-27 13:06:54,840 - ftms - ERROR - Error discovering devices: 'FTMSDeviceSimulator' object has no attribute 'discover_devices'
2025-04-27 13:11:51,028 - web - ERROR - Error discovering devices: Object of type SimulatedBLEDevice is not JSON serializable
2025-04-27 16:50:54,212 - web - ERROR - Error discovering devices: Object of type BLEDevice is not JSON serializable
2025-04-27 16:51:02,577 - web - ERROR - Error discovering devices: Object of type BLEDevice is not JSON serializable
2025-04-27 16:56:03,127 - web - ERROR - Error discovering devices: 'str' object has no attribute 'name'
2025-04-27 17:05:38,417 - web - ERROR - Error connecting to device: 'FTMSDeviceManager' object has no attribute 'connect'
2025-04-27 17:09:09,055 - web - ERROR - Error connecting to device: name 'asyncio' is not defined
Traceback (most recent call last):
  File "C:\Users\dougl\rogue_garmin_bridge\src\web\app.py", line 212, in connect_device
    success = asyncio.run(ftms_manager.connect(device_address))
              ^^^^^^^
NameError: name 'asyncio' is not defined. Did you forget to import 'asyncio'
2025-04-27 17:10:12,123 - ftms_connector - ERROR - Error initializing FTMS service: 'FitnessMachineService' object has no attribute 'enable_notifications'
2025-04-27 17:10:15,562 - ftms - ERROR - Failed to connect to device C9:02:CB:68:17:C1
2025-04-27 17:10:24,806 - ftms_connector - ERROR - Error initializing FTMS service: 'FitnessMachineService' object has no attribute 'enable_notifications'
2025-04-27 17:10:30,162 - ftms - ERROR - Connection attempt timed out after 15 seconds
2025-04-27 17:10:33,725 - ftms - ERROR - Connection attempt timed out after 15 seconds
2025-04-27 17:12:58,302 - ftms_connector - ERROR - Error initializing FTMS service: 'FitnessMachineService' object has no attribute 'enable_notifications'
2025-04-27 17:13:01,636 - ftms - ERROR - Failed to connect to device C9:02:CB:68:17:C1
2025-04-27 17:15:30,766 - ftms_connector - ERROR - Error connecting to device after maximum retries: 'NoneType' object has no attribute 'bluetooth_address'
2025-04-27 17:15:30,768 - ftms - ERROR - Failed to connect to device C9:02:CB:68:17:C1
2025-04-27 17:16:58,842 - ftms - ERROR - Connection attempt timed out after 15 seconds
2025-04-27 17:17:01,784 - ftms - ERROR - Connection attempt timed out after 15 seconds
2025-04-27 17:18:20,065 - ftms_connector - ERROR - Error initializing FTMS service: 'FitnessMachineService' object has no attribute 'set_rower_data_handler'
2025-04-27 17:18:23,426 - ftms - ERROR - Failed to connect to device C9:02:CB:68:17:C1
2025-04-27 17:20:23,079 - workout_manager - ERROR - Cannot start workout: No device ID provided
2025-04-27 17:20:29,788 - workout_manager - ERROR - Cannot start workout: No device ID provided
2025-04-27 17:20:51,877 - workout_manager - ERROR - Cannot start workout: No device ID provided
2025-04-27 17:20:51,954 - workout_manager - ERROR - Cannot start workout: No device ID provided
2025-04-27 17:20:52,206 - workout_manager - ERROR - Cannot start workout: No device ID provided
2025-04-27 17:20:52,405 - workout_manager - ERROR - Cannot start workout: No device ID provided
2025-04-27 17:20:52,559 - workout_manager - ERROR - Cannot start workout: No device ID provided
2025-04-27 17:20:52,591 - workout_manager - ERROR - Cannot start workout: No device ID provided
2025-04-27 17:21:07,873 - workout_manager - ERROR - Cannot start workout: No device ID provided
2025-04-27 17:21:08,198 - workout_manager - ERROR - Cannot start workout: No device ID provided
2025-04-27 17:21:08,291 - workout_manager - ERROR - Cannot start workout: No device ID provided
2025-04-27 17:38:22,317 - ftms - ERROR - Connection attempt timed out after 15 seconds
2025-04-27 17:47:48,941 - workout_manager - ERROR - Error starting workout: Database.start_workout() got an unexpected keyword argument 'start_time'
2025-04-27 17:47:54,951 - workout_manager - ERROR - Error starting workout: Database.start_workout() got an unexpected keyword argument 'start_time'
2025-04-27 17:54:41,383 - web - ERROR - Error ending workout: WorkoutManager.end_workout() takes 1 positional argument but 2 were given
2025-04-27 18:02:38,531 - workout_manager - ERROR - Error ending workout: 'WorkoutManager' object has no attribute 'fit_converter'
2025-04-27 18:02:51,591 - workout_manager - ERROR - Error ending workout: 'WorkoutManager' object has no attribute 'fit_converter'
2025-04-27 18:07:05,617 - ftms_connector - ERROR - Error during disconnect: 'NoneType' object is not iterable
2025-04-27 18:07:08,262 - ftms - ERROR - Connection attempt timed out after 15 seconds
2025-04-27 18:07:08,372 - ftms - ERROR - Connection attempt timed out after 15 seconds
2025-04-27 18:07:08,409 - ftms - ERROR - Connection attempt timed out after 15 seconds
2025-04-27 18:07:08,411 - ftms - ERROR - Connection attempt timed out after 15 seconds
2025-04-27 18:07:08,684 - ftms - ERROR - Connection attempt timed out after 15 seconds
2025-04-27 18:17:46,202 - ftms_connector - ERROR - Error initializing FTMS service: 'FitnessMachineService' object has no attribute 'enable_notifications'
2025-04-27 18:17:49,592 - ftms - ERROR - Failed to connect to device C9:02:CB:68:17:C1
2025-04-27 18:18:03,969 - ftms_connector - ERROR - Error initializing FTMS service: 'FitnessMachineService' object has no attribute 'enable_notifications'
2025-04-27 18:18:07,210 - ftms - ERROR - Failed to connect to device C9:02:CB:68:17:C1
2025-04-27 18:18:15,976 - ftms_connector - ERROR - Error initializing FTMS service: 'FitnessMachineService' object has no attribute 'enable_notifications'
2025-04-27 18:18:19,308 - ftms - ERROR - Failed to connect to device C9:02:CB:68:17:C1
2025-04-27 18:18:42,493 - ftms_connector - ERROR - Error initializing FTMS service: 'FitnessMachineService' object has no attribute 'enable_notifications'
2025-04-27 18:18:45,795 - ftms - ERROR - Failed to connect to device C9:02:CB:68:17:C1
2025-04-27 18:18:55,409 - ftms_connector - ERROR - Error initializing FTMS service: 'FitnessMachineService' object has no attribute 'enable_notifications'
2025-04-27 18:18:58,710 - ftms - ERROR - Failed to connect to device C9:02:CB:68:17:C1
2025-04-27 18:19:20,203 - ftms_connector - ERROR - Error initializing FTMS service: 'FitnessMachineService' object has no attribute 'enable_notifications'
2025-04-27 18:19:23,505 - ftms - ERROR - Failed to connect to device C9:02:CB:68:17:C1
2025-04-27 18:51:03,560 - ftms_connector - ERROR - Error initializing FTMS service or enabling notifications: 'FitnessMachineService' object has no attribute 'set_rower_data_handler'
2025-04-27 18:51:06,807 - ftms - ERROR - Failed to connect to device C9:02:CB:68:17:C1
2025-04-27 18:51:21,776 - ftms_connector - ERROR - Error initializing FTMS service or enabling notifications: 'FitnessMachineService' object has no attribute 'set_rower_data_handler'
2025-04-27 18:51:25,055 - ftms - ERROR - Failed to connect to device C9:02:CB:68:17:C1
2025-04-27 18:53:54,325 - ftms_connector - ERROR - Error initializing FTMS service or enabling notifications: 'FitnessMachineService' object has no attribute 'set_rower_data_handler'
2025-04-27 18:53:57,692 - ftms - ERROR - Failed to connect to device C9:02:CB:68:17:C1
2025-04-27 18:54:05,787 - ftms_connector - ERROR - Error initializing FTMS service or enabling notifications: 'FitnessMachineService' object has no attribute 'set_rower_data_handler'
2025-04-27 18:54:09,034 - ftms - ERROR - Failed to connect to device C9:02:CB:68:17:C1
2025-04-27 18:54:21,242 - ftms_connector - ERROR - Error initializing FTMS service or enabling notifications: 'FitnessMachineService' object has no attribute 'set_rower_data_handler'
2025-04-27 18:54:24,546 - ftms - ERROR - Failed to connect to device C9:02:CB:68:17:C1
2025-04-27 18:56:16,459 - ftms_connector - ERROR - Error initializing FTMS service or enabling notifications: 'FitnessMachineService' object has no attribute 'set_rower_data_handler'
2025-04-27 18:56:19,612 - ftms - ERROR - Failed to connect to device C9:02:CB:68:17:C1
2025-04-27 19:17:31,884 - ftms - ERROR - Connection attempt timed out after 15 seconds
2025-04-27 19:20:05,987 - ftms_connector - ERROR - Error initializing FTMS service or enabling notifications: 'FitnessMachineService' object has no attribute 'set_rower_data_handler'
2025-04-27 19:20:09,173 - ftms - ERROR - Failed to connect to device C9:02:CB:68:17:C1
2025-04-27 19:26:39,812 - web - ERROR - Asyncio background loop is not running.
2025-04-27 19:27:51,733 - web - ERROR - Asyncio background loop is not running.
2025-04-27 19:27:56,278 - web - ERROR - Asyncio background loop is not running.
2025-04-27 19:29:01,782 - web - ERROR - Error discovering devices: A coroutine object is required
Traceback (most recent call last):
  File "C:\Users\dougl\rogue_garmin_bridge\src\web\app.py", line 123, in discover_devices
    future = asyncio.run_coroutine_threadsafe(ftms_manager.discover_devices(), background_loop)
             ^^^^^^^^^^^^^^^^^^^^^^^^^^^^^^^^^^^^^^^^^^^^^^^^^^^^^^^^^^^^^^^^^^^^^^^^^^^^^^^^^^
  File "C:\Users\dougl\AppData\Local\Programs\Python\Python312\Lib\asyncio\tasks.py", line 937, in run_coroutine_threadsafe
    raise TypeError('A coroutine object is required')
TypeError: A coroutine object is required
2025-04-27 19:29:09,279 - web - ERROR - Error discovering devices: A coroutine object is required
Traceback (most recent call last):
  File "C:\Users\dougl\rogue_garmin_bridge\src\web\app.py", line 123, in discover_devices
    future = asyncio.run_coroutine_threadsafe(ftms_manager.discover_devices(), background_loop)
             ^^^^^^^^^^^^^^^^^^^^^^^^^^^^^^^^^^^^^^^^^^^^^^^^^^^^^^^^^^^^^^^^^^^^^^^^^^^^^^^^^^
  File "C:\Users\dougl\AppData\Local\Programs\Python\Python312\Lib\asyncio\tasks.py", line 937, in run_coroutine_threadsafe
    raise TypeError('A coroutine object is required')
TypeError: A coroutine object is required
2025-04-27 19:29:30,042 - web - ERROR - Error discovering devices: A coroutine object is required
Traceback (most recent call last):
  File "C:\Users\dougl\rogue_garmin_bridge\src\web\app.py", line 123, in discover_devices
    future = asyncio.run_coroutine_threadsafe(ftms_manager.discover_devices(), background_loop)
             ^^^^^^^^^^^^^^^^^^^^^^^^^^^^^^^^^^^^^^^^^^^^^^^^^^^^^^^^^^^^^^^^^^^^^^^^^^^^^^^^^^
  File "C:\Users\dougl\AppData\Local\Programs\Python\Python312\Lib\asyncio\tasks.py", line 937, in run_coroutine_threadsafe
    raise TypeError('A coroutine object is required')
TypeError: A coroutine object is required
2025-04-27 19:31:08,456 - ftms_connector - ERROR - Error processing indoor bike data: 'IndoorBikeData' object has no attribute 'get'
Traceback (most recent call last):
  File "C:\Users\dougl\rogue_garmin_bridge\src\ftms\ftms_connector.py", line 407, in _handle_indoor_bike_data
    'timestamp': data.get('elapsed_time', 0),
                ^^^^^^^^
AttributeError: 'IndoorBikeData' object has no attribute 'get'
2025-04-27 19:31:09,387 - ftms_connector - ERROR - Error processing indoor bike data: 'IndoorBikeData' object has no attribute 'get'
Traceback (most recent call last):
  File "C:\Users\dougl\rogue_garmin_bridge\src\ftms\ftms_connector.py", line 407, in _handle_indoor_bike_data
    'timestamp': data.get('elapsed_time', 0),
                ^^^^^^^^
AttributeError: 'IndoorBikeData' object has no attribute 'get'
2025-04-27 19:31:10,376 - ftms_connector - ERROR - Error processing indoor bike data: 'IndoorBikeData' object has no attribute 'get'
Traceback (most recent call last):
  File "C:\Users\dougl\rogue_garmin_bridge\src\ftms\ftms_connector.py", line 407, in _handle_indoor_bike_data
    'timestamp': data.get('elapsed_time', 0),
                ^^^^^^^^
AttributeError: 'IndoorBikeData' object has no attribute 'get'
2025-04-27 19:31:11,396 - ftms_connector - ERROR - Error processing indoor bike data: 'IndoorBikeData' object has no attribute 'get'
Traceback (most recent call last):
  File "C:\Users\dougl\rogue_garmin_bridge\src\ftms\ftms_connector.py", line 407, in _handle_indoor_bike_data
    'timestamp': data.get('elapsed_time', 0),
                ^^^^^^^^
AttributeError: 'IndoorBikeData' object has no attribute 'get'
2025-04-27 19:31:12,387 - ftms_connector - ERROR - Error processing indoor bike data: 'IndoorBikeData' object has no attribute 'get'
Traceback (most recent call last):
  File "C:\Users\dougl\rogue_garmin_bridge\src\ftms\ftms_connector.py", line 407, in _handle_indoor_bike_data
    'timestamp': data.get('elapsed_time', 0),
                ^^^^^^^^
AttributeError: 'IndoorBikeData' object has no attribute 'get'
2025-04-27 19:31:13,426 - ftms_connector - ERROR - Error processing indoor bike data: 'IndoorBikeData' object has no attribute 'get'
Traceback (most recent call last):
  File "C:\Users\dougl\rogue_garmin_bridge\src\ftms\ftms_connector.py", line 407, in _handle_indoor_bike_data
    'timestamp': data.get('elapsed_time', 0),
                ^^^^^^^^
AttributeError: 'IndoorBikeData' object has no attribute 'get'
2025-04-27 19:31:14,397 - ftms_connector - ERROR - Error processing indoor bike data: 'IndoorBikeData' object has no attribute 'get'
Traceback (most recent call last):
  File "C:\Users\dougl\rogue_garmin_bridge\src\ftms\ftms_connector.py", line 407, in _handle_indoor_bike_data
    'timestamp': data.get('elapsed_time', 0),
                ^^^^^^^^
AttributeError: 'IndoorBikeData' object has no attribute 'get'
2025-04-27 19:31:15,418 - ftms_connector - ERROR - Error processing indoor bike data: 'IndoorBikeData' object has no attribute 'get'
Traceback (most recent call last):
  File "C:\Users\dougl\rogue_garmin_bridge\src\ftms\ftms_connector.py", line 407, in _handle_indoor_bike_data
    'timestamp': data.get('elapsed_time', 0),
                ^^^^^^^^
AttributeError: 'IndoorBikeData' object has no attribute 'get'
2025-04-27 19:31:16,378 - ftms_connector - ERROR - Error processing indoor bike data: 'IndoorBikeData' object has no attribute 'get'
Traceback (most recent call last):
  File "C:\Users\dougl\rogue_garmin_bridge\src\ftms\ftms_connector.py", line 407, in _handle_indoor_bike_data
    'timestamp': data.get('elapsed_time', 0),
                ^^^^^^^^
AttributeError: 'IndoorBikeData' object has no attribute 'get'
2025-04-27 19:31:17,397 - ftms_connector - ERROR - Error processing indoor bike data: 'IndoorBikeData' object has no attribute 'get'
Traceback (most recent call last):
  File "C:\Users\dougl\rogue_garmin_bridge\src\ftms\ftms_connector.py", line 407, in _handle_indoor_bike_data
    'timestamp': data.get('elapsed_time', 0),
                ^^^^^^^^
AttributeError: 'IndoorBikeData' object has no attribute 'get'
2025-04-27 19:31:18,417 - ftms_connector - ERROR - Error processing indoor bike data: 'IndoorBikeData' object has no attribute 'get'
Traceback (most recent call last):
  File "C:\Users\dougl\rogue_garmin_bridge\src\ftms\ftms_connector.py", line 407, in _handle_indoor_bike_data
    'timestamp': data.get('elapsed_time', 0),
                ^^^^^^^^
AttributeError: 'IndoorBikeData' object has no attribute 'get'
2025-04-27 19:31:19,377 - ftms_connector - ERROR - Error processing indoor bike data: 'IndoorBikeData' object has no attribute 'get'
Traceback (most recent call last):
  File "C:\Users\dougl\rogue_garmin_bridge\src\ftms\ftms_connector.py", line 407, in _handle_indoor_bike_data
    'timestamp': data.get('elapsed_time', 0),
                ^^^^^^^^
AttributeError: 'IndoorBikeData' object has no attribute 'get'
2025-04-27 19:31:20,427 - ftms_connector - ERROR - Error processing indoor bike data: 'IndoorBikeData' object has no attribute 'get'
Traceback (most recent call last):
  File "C:\Users\dougl\rogue_garmin_bridge\src\ftms\ftms_connector.py", line 407, in _handle_indoor_bike_data
    'timestamp': data.get('elapsed_time', 0),
                ^^^^^^^^
AttributeError: 'IndoorBikeData' object has no attribute 'get'
2025-04-27 19:31:21,387 - ftms_connector - ERROR - Error processing indoor bike data: 'IndoorBikeData' object has no attribute 'get'
Traceback (most recent call last):
  File "C:\Users\dougl\rogue_garmin_bridge\src\ftms\ftms_connector.py", line 407, in _handle_indoor_bike_data
    'timestamp': data.get('elapsed_time', 0),
                ^^^^^^^^
AttributeError: 'IndoorBikeData' object has no attribute 'get'
2025-04-27 19:31:22,408 - ftms_connector - ERROR - Error processing indoor bike data: 'IndoorBikeData' object has no attribute 'get'
Traceback (most recent call last):
  File "C:\Users\dougl\rogue_garmin_bridge\src\ftms\ftms_connector.py", line 407, in _handle_indoor_bike_data
    'timestamp': data.get('elapsed_time', 0),
                ^^^^^^^^
AttributeError: 'IndoorBikeData' object has no attribute 'get'
2025-04-27 19:31:23,397 - ftms_connector - ERROR - Error processing indoor bike data: 'IndoorBikeData' object has no attribute 'get'
Traceback (most recent call last):
  File "C:\Users\dougl\rogue_garmin_bridge\src\ftms\ftms_connector.py", line 407, in _handle_indoor_bike_data
    'timestamp': data.get('elapsed_time', 0),
                ^^^^^^^^
AttributeError: 'IndoorBikeData' object has no attribute 'get'
2025-04-27 19:31:24,388 - ftms_connector - ERROR - Error processing indoor bike data: 'IndoorBikeData' object has no attribute 'get'
Traceback (most recent call last):
  File "C:\Users\dougl\rogue_garmin_bridge\src\ftms\ftms_connector.py", line 407, in _handle_indoor_bike_data
    'timestamp': data.get('elapsed_time', 0),
                ^^^^^^^^
AttributeError: 'IndoorBikeData' object has no attribute 'get'
2025-04-27 19:31:25,406 - ftms_connector - ERROR - Error processing indoor bike data: 'IndoorBikeData' object has no attribute 'get'
Traceback (most recent call last):
  File "C:\Users\dougl\rogue_garmin_bridge\src\ftms\ftms_connector.py", line 407, in _handle_indoor_bike_data
    'timestamp': data.get('elapsed_time', 0),
                ^^^^^^^^
AttributeError: 'IndoorBikeData' object has no attribute 'get'
2025-04-27 19:31:26,397 - ftms_connector - ERROR - Error processing indoor bike data: 'IndoorBikeData' object has no attribute 'get'
Traceback (most recent call last):
  File "C:\Users\dougl\rogue_garmin_bridge\src\ftms\ftms_connector.py", line 407, in _handle_indoor_bike_data
    'timestamp': data.get('elapsed_time', 0),
                ^^^^^^^^
AttributeError: 'IndoorBikeData' object has no attribute 'get'
2025-04-27 19:31:27,388 - ftms_connector - ERROR - Error processing indoor bike data: 'IndoorBikeData' object has no attribute 'get'
Traceback (most recent call last):
  File "C:\Users\dougl\rogue_garmin_bridge\src\ftms\ftms_connector.py", line 407, in _handle_indoor_bike_data
    'timestamp': data.get('elapsed_time', 0),
                ^^^^^^^^
AttributeError: 'IndoorBikeData' object has no attribute 'get'
2025-04-27 19:31:28,424 - ftms_connector - ERROR - Error processing indoor bike data: 'IndoorBikeData' object has no attribute 'get'
Traceback (most recent call last):
  File "C:\Users\dougl\rogue_garmin_bridge\src\ftms\ftms_connector.py", line 407, in _handle_indoor_bike_data
    'timestamp': data.get('elapsed_time', 0),
                ^^^^^^^^
AttributeError: 'IndoorBikeData' object has no attribute 'get'
2025-04-27 19:31:29,398 - ftms_connector - ERROR - Error processing indoor bike data: 'IndoorBikeData' object has no attribute 'get'
Traceback (most recent call last):
  File "C:\Users\dougl\rogue_garmin_bridge\src\ftms\ftms_connector.py", line 407, in _handle_indoor_bike_data
    'timestamp': data.get('elapsed_time', 0),
                ^^^^^^^^
AttributeError: 'IndoorBikeData' object has no attribute 'get'
2025-04-27 19:31:30,448 - ftms_connector - ERROR - Error processing indoor bike data: 'IndoorBikeData' object has no attribute 'get'
Traceback (most recent call last):
  File "C:\Users\dougl\rogue_garmin_bridge\src\ftms\ftms_connector.py", line 407, in _handle_indoor_bike_data
    'timestamp': data.get('elapsed_time', 0),
                ^^^^^^^^
AttributeError: 'IndoorBikeData' object has no attribute 'get'
2025-04-27 19:31:31,378 - ftms_connector - ERROR - Error processing indoor bike data: 'IndoorBikeData' object has no attribute 'get'
Traceback (most recent call last):
  File "C:\Users\dougl\rogue_garmin_bridge\src\ftms\ftms_connector.py", line 407, in _handle_indoor_bike_data
    'timestamp': data.get('elapsed_time', 0),
                ^^^^^^^^
AttributeError: 'IndoorBikeData' object has no attribute 'get'
2025-04-27 19:31:32,505 - ftms_connector - ERROR - Error processing indoor bike data: 'IndoorBikeData' object has no attribute 'get'
Traceback (most recent call last):
  File "C:\Users\dougl\rogue_garmin_bridge\src\ftms\ftms_connector.py", line 407, in _handle_indoor_bike_data
    'timestamp': data.get('elapsed_time', 0),
                ^^^^^^^^
AttributeError: 'IndoorBikeData' object has no attribute 'get'
2025-04-27 19:31:33,448 - ftms_connector - ERROR - Error processing indoor bike data: 'IndoorBikeData' object has no attribute 'get'
Traceback (most recent call last):
  File "C:\Users\dougl\rogue_garmin_bridge\src\ftms\ftms_connector.py", line 407, in _handle_indoor_bike_data
    'timestamp': data.get('elapsed_time', 0),
                ^^^^^^^^
AttributeError: 'IndoorBikeData' object has no attribute 'get'
2025-04-29 19:45:49,626 - web - ERROR - Error getting workout summary: 'WorkoutManager' object has no attribute 'get_workout_summary_metrics'
2025-04-29 19:45:49,685 - web - ERROR - Error getting workout summary: 'WorkoutManager' object has no attribute 'get_workout_summary_metrics'
2025-04-29 19:45:50,377 - web - ERROR - Error getting workout summary: 'WorkoutManager' object has no attribute 'get_workout_summary_metrics'
2025-04-29 19:45:51,704 - web - ERROR - Error getting workout summary: 'WorkoutManager' object has no attribute 'get_workout_summary_metrics'
2025-04-29 19:45:52,386 - web - ERROR - Error getting workout summary: 'WorkoutManager' object has no attribute 'get_workout_summary_metrics'
2025-04-29 19:45:53,693 - web - ERROR - Error getting workout summary: 'WorkoutManager' object has no attribute 'get_workout_summary_metrics'
2025-04-29 19:45:54,391 - web - ERROR - Error getting workout summary: 'WorkoutManager' object has no attribute 'get_workout_summary_metrics'
2025-04-29 19:45:55,708 - web - ERROR - Error getting workout summary: 'WorkoutManager' object has no attribute 'get_workout_summary_metrics'
2025-04-29 19:45:56,379 - web - ERROR - Error getting workout summary: 'WorkoutManager' object has no attribute 'get_workout_summary_metrics'
2025-04-29 19:45:57,697 - web - ERROR - Error getting workout summary: 'WorkoutManager' object has no attribute 'get_workout_summary_metrics'
2025-04-29 19:45:58,386 - web - ERROR - Error getting workout summary: 'WorkoutManager' object has no attribute 'get_workout_summary_metrics'
2025-04-29 19:45:59,698 - web - ERROR - Error getting workout summary: 'WorkoutManager' object has no attribute 'get_workout_summary_metrics'
2025-04-29 19:46:00,382 - web - ERROR - Error getting workout summary: 'WorkoutManager' object has no attribute 'get_workout_summary_metrics'
2025-04-29 19:46:01,689 - web - ERROR - Error getting workout summary: 'WorkoutManager' object has no attribute 'get_workout_summary_metrics'
2025-04-29 19:46:02,393 - web - ERROR - Error getting workout summary: 'WorkoutManager' object has no attribute 'get_workout_summary_metrics'
2025-04-29 19:46:03,704 - web - ERROR - Error getting workout summary: 'WorkoutManager' object has no attribute 'get_workout_summary_metrics'
2025-04-29 19:46:04,382 - web - ERROR - Error getting workout summary: 'WorkoutManager' object has no attribute 'get_workout_summary_metrics'
2025-04-29 19:46:05,684 - web - ERROR - Error getting workout summary: 'WorkoutManager' object has no attribute 'get_workout_summary_metrics'
2025-04-29 19:46:06,380 - web - ERROR - Error getting workout summary: 'WorkoutManager' object has no attribute 'get_workout_summary_metrics'
2025-04-29 19:46:07,696 - web - ERROR - Error getting workout summary: 'WorkoutManager' object has no attribute 'get_workout_summary_metrics'
2025-04-29 19:46:13,570 - web - ERROR - Error getting workout summary: 'WorkoutManager' object has no attribute 'get_workout_summary_metrics'
2025-04-29 19:46:13,830 - web - ERROR - Error getting workout summary: 'WorkoutManager' object has no attribute 'get_workout_summary_metrics'
2025-04-29 19:46:14,527 - web - ERROR - Error getting workout summary: 'WorkoutManager' object has no attribute 'get_workout_summary_metrics'
2025-04-29 19:46:15,834 - web - ERROR - Error getting workout summary: 'WorkoutManager' object has no attribute 'get_workout_summary_metrics'
2025-04-29 19:46:16,526 - web - ERROR - Error getting workout summary: 'WorkoutManager' object has no attribute 'get_workout_summary_metrics'
2025-04-29 19:46:17,849 - web - ERROR - Error getting workout summary: 'WorkoutManager' object has no attribute 'get_workout_summary_metrics'
2025-04-29 19:46:18,531 - web - ERROR - Error getting workout summary: 'WorkoutManager' object has no attribute 'get_workout_summary_metrics'
2025-04-29 19:46:19,833 - web - ERROR - Error getting workout summary: 'WorkoutManager' object has no attribute 'get_workout_summary_metrics'
2025-04-29 19:46:20,534 - web - ERROR - Error getting workout summary: 'WorkoutManager' object has no attribute 'get_workout_summary_metrics'
2025-04-29 19:46:21,832 - web - ERROR - Error getting workout summary: 'WorkoutManager' object has no attribute 'get_workout_summary_metrics'
2025-04-29 19:46:22,532 - web - ERROR - Error getting workout summary: 'WorkoutManager' object has no attribute 'get_workout_summary_metrics'
2025-04-29 19:46:23,832 - web - ERROR - Error getting workout summary: 'WorkoutManager' object has no attribute 'get_workout_summary_metrics'
2025-04-29 19:46:24,519 - web - ERROR - Error getting workout summary: 'WorkoutManager' object has no attribute 'get_workout_summary_metrics'
2025-04-29 19:46:25,835 - web - ERROR - Error getting workout summary: 'WorkoutManager' object has no attribute 'get_workout_summary_metrics'
2025-04-29 19:50:25,420 - database - ERROR - Error adding workout data for workout 83, timestamp 0.681871: SQLite objects created in a thread can only be used in that same thread. The object was created in thread id 25448 and this is thread id 38576.
Traceback (most recent call last):
  File "C:\Users\dougl\rogue_garmin_bridge\src\data\database.py", line 347, in add_workout_data
    self.conn.commit()
sqlite3.ProgrammingError: SQLite objects created in a thread can only be used in that same thread. The object was created in thread id 25448 and this is thread id 38576.
2025-04-29 19:50:25,425 - workout_manager - ERROR - Failed to add data point to workout 83
2025-04-29 19:50:27,531 - ftms_connector - ERROR - AttributeError processing indoor bike data: 'NoneType' object has no attribute 'commit'. Data object: IndoorBikeData(instant_speed=12.55, average_speed=0.78, instant_cadence=21.0, average_cadence=21.0, total_distance=16, resistance_level=None, instant_power=18, average_power=18, total_energy=0, energy_per_hour=0, energy_per_minute=0, heart_rate=89, metabolic_equivalent=None, elapsed_time=6, remaining_time=None)
Traceback (most recent call last):
  File "C:\Users\dougl\rogue_garmin_bridge\src\ftms\ftms_connector.py", line 423, in _handle_indoor_bike_data
    callback(processed_data)
  File "C:\Users\dougl\rogue_garmin_bridge\src\ftms\ftms_manager.py", line 83, in _handle_data
    self._notify_data_callbacks(data)
  File "C:\Users\dougl\rogue_garmin_bridge\src\ftms\ftms_manager.py", line 90, in _notify_data_callbacks
    self._handle_ftms_data(data)
  File "C:\Users\dougl\rogue_garmin_bridge\src\ftms\ftms_manager.py", line 299, in _handle_ftms_data
    self.workout_manager.add_data_point(data)
  File "C:\Users\dougl\rogue_garmin_bridge\src\data\workout_manager.py", line 265, in add_data_point
    success = self.database.add_workout_data(
              ^^^^^^^^^^^^^^^^^^^^^^^^^^^^^^^
  File "C:\Users\dougl\rogue_garmin_bridge\src\data\database.py", line 347, in add_workout_data
    self.conn.commit()
    ^^^^^^^^^^^^^^^^
AttributeError: 'NoneType' object has no attribute 'commit'
2025-04-29 19:50:33,075 - database - ERROR - Error adding workout data for workout 83, timestamp 2.853219: database is locked
Traceback (most recent call last):
  File "C:\Users\dougl\rogue_garmin_bridge\src\data\database.py", line 339, in add_workout_data
    self.cursor.execute(
sqlite3.OperationalError: database is locked
2025-04-29 19:50:33,078 - workout_manager - ERROR - Failed to add data point to workout 83
2025-04-29 19:50:38,499 - database - ERROR - Error adding workout data for workout 83, timestamp 8.395774: database is locked
Traceback (most recent call last):
  File "C:\Users\dougl\rogue_garmin_bridge\src\data\database.py", line 339, in add_workout_data
    self.cursor.execute(
sqlite3.OperationalError: database is locked
2025-04-29 19:50:38,499 - workout_manager - ERROR - Failed to add data point to workout 83
2025-04-29 19:50:43,972 - database - ERROR - Error adding workout data for workout 83, timestamp 13.818413: database is locked
Traceback (most recent call last):
  File "C:\Users\dougl\rogue_garmin_bridge\src\data\database.py", line 339, in add_workout_data
    self.cursor.execute(
sqlite3.OperationalError: database is locked
2025-04-29 19:50:43,973 - workout_manager - ERROR - Failed to add data point to workout 83
2025-04-29 19:50:49,485 - database - ERROR - Error adding workout data for workout 83, timestamp 19.292214: database is locked
Traceback (most recent call last):
  File "C:\Users\dougl\rogue_garmin_bridge\src\data\database.py", line 339, in add_workout_data
    self.cursor.execute(
sqlite3.OperationalError: database is locked
2025-04-29 19:50:49,487 - workout_manager - ERROR - Failed to add data point to workout 83
2025-04-29 19:50:54,983 - database - ERROR - Error adding workout data for workout 83, timestamp 24.804143: database is locked
Traceback (most recent call last):
  File "C:\Users\dougl\rogue_garmin_bridge\src\data\database.py", line 339, in add_workout_data
    self.cursor.execute(
sqlite3.OperationalError: database is locked
2025-04-29 19:50:54,984 - workout_manager - ERROR - Failed to add data point to workout 83
2025-04-29 19:51:00,498 - database - ERROR - Error adding workout data for workout 83, timestamp 30.302045: database is locked
Traceback (most recent call last):
  File "C:\Users\dougl\rogue_garmin_bridge\src\data\database.py", line 339, in add_workout_data
    self.cursor.execute(
sqlite3.OperationalError: database is locked
2025-04-29 19:51:00,500 - workout_manager - ERROR - Failed to add data point to workout 83
2025-04-29 19:51:06,041 - database - ERROR - Error adding workout data for workout 83, timestamp 35.818930: database is locked
Traceback (most recent call last):
  File "C:\Users\dougl\rogue_garmin_bridge\src\data\database.py", line 339, in add_workout_data
    self.cursor.execute(
sqlite3.OperationalError: database is locked
2025-04-29 19:51:06,042 - workout_manager - ERROR - Failed to add data point to workout 83
2025-04-29 19:51:11,558 - database - ERROR - Error adding workout data for workout 83, timestamp 41.361323: database is locked
Traceback (most recent call last):
  File "C:\Users\dougl\rogue_garmin_bridge\src\data\database.py", line 339, in add_workout_data
    self.cursor.execute(
sqlite3.OperationalError: database is locked
2025-04-29 19:51:11,560 - workout_manager - ERROR - Failed to add data point to workout 83
2025-04-29 19:51:17,043 - database - ERROR - Error adding workout data for workout 83, timestamp 46.878251: database is locked
Traceback (most recent call last):
  File "C:\Users\dougl\rogue_garmin_bridge\src\data\database.py", line 339, in add_workout_data
    self.cursor.execute(
sqlite3.OperationalError: database is locked
2025-04-29 19:51:17,045 - workout_manager - ERROR - Failed to add data point to workout 83
2025-04-29 19:51:22,572 - database - ERROR - Error adding workout data for workout 83, timestamp 52.364046: database is locked
Traceback (most recent call last):
  File "C:\Users\dougl\rogue_garmin_bridge\src\data\database.py", line 339, in add_workout_data
    self.cursor.execute(
sqlite3.OperationalError: database is locked
2025-04-29 19:51:22,574 - workout_manager - ERROR - Failed to add data point to workout 83
2025-04-29 19:51:27,980 - database - ERROR - Error adding workout data for workout 83, timestamp 57.891984: database is locked
Traceback (most recent call last):
  File "C:\Users\dougl\rogue_garmin_bridge\src\data\database.py", line 339, in add_workout_data
    self.cursor.execute(
sqlite3.OperationalError: database is locked
2025-04-29 19:51:27,982 - workout_manager - ERROR - Failed to add data point to workout 83
2025-04-29 19:51:33,453 - database - ERROR - Error adding workout data for workout 83, timestamp 63.300150: database is locked
Traceback (most recent call last):
  File "C:\Users\dougl\rogue_garmin_bridge\src\data\database.py", line 339, in add_workout_data
    self.cursor.execute(
sqlite3.OperationalError: database is locked
2025-04-29 19:51:33,454 - workout_manager - ERROR - Failed to add data point to workout 83
2025-04-29 19:51:38,961 - database - ERROR - Error adding workout data for workout 83, timestamp 68.771712: database is locked
Traceback (most recent call last):
  File "C:\Users\dougl\rogue_garmin_bridge\src\data\database.py", line 339, in add_workout_data
    self.cursor.execute(
sqlite3.OperationalError: database is locked
2025-04-29 19:51:38,962 - workout_manager - ERROR - Failed to add data point to workout 83
2025-04-29 19:51:44,491 - database - ERROR - Error adding workout data for workout 83, timestamp 74.281098: database is locked
Traceback (most recent call last):
  File "C:\Users\dougl\rogue_garmin_bridge\src\data\database.py", line 339, in add_workout_data
    self.cursor.execute(
sqlite3.OperationalError: database is locked
2025-04-29 19:51:44,493 - workout_manager - ERROR - Failed to add data point to workout 83
2025-04-29 19:51:45,559 - database - ERROR - Error ending workout: database is locked
2025-04-29 19:51:45,560 - workout_manager - ERROR - Error ending workout: SQLite objects created in a thread can only be used in that same thread. The object was created in thread id 32724 and this is thread id 45376.
2025-04-29 19:51:47,286 - database - ERROR - Error ending workout: database is locked
2025-04-29 19:51:47,287 - workout_manager - ERROR - Error ending workout: SQLite objects created in a thread can only be used in that same thread. The object was created in thread id 32724 and this is thread id 40284.
2025-04-29 19:51:50,020 - database - ERROR - Error adding workout data for workout 83, timestamp 79.811638: database is locked
Traceback (most recent call last):
  File "C:\Users\dougl\rogue_garmin_bridge\src\data\database.py", line 339, in add_workout_data
    self.cursor.execute(
sqlite3.OperationalError: database is locked
2025-04-29 19:51:50,021 - workout_manager - ERROR - Failed to add data point to workout 83
2025-04-29 19:51:50,858 - database - ERROR - Error ending workout: database is locked
2025-04-29 19:51:50,859 - workout_manager - ERROR - Failed to update workout 83 in database
2025-04-29 19:51:51,088 - database - ERROR - Error ending workout: database is locked
2025-04-29 19:51:51,089 - workout_manager - ERROR - Failed to update workout 83 in database
2025-04-29 19:51:55,550 - database - ERROR - Error adding workout data for workout 83, timestamp 85.338522: database is locked
Traceback (most recent call last):
  File "C:\Users\dougl\rogue_garmin_bridge\src\data\database.py", line 339, in add_workout_data
    self.cursor.execute(
sqlite3.OperationalError: database is locked
2025-04-29 19:51:55,552 - workout_manager - ERROR - Failed to add data point to workout None
