2025-04-27 13:04:01,739 - ftms - ERROR - Error discovering devices: 'FTMSDeviceSimulator' object has no attribute 'discover_devices'
2025-04-27 13:04:01,950 - ftms - ERROR - Error discovering devices: 'FTMSDeviceSimulator' object has no attribute 'discover_devices'
2025-04-27 13:04:06,742 - ftms - ERROR - Error discovering devices: 'FTMSDeviceSimulator' object has no attribute 'discover_devices'
2025-04-27 13:04:06,953 - ftms - ERROR - Error discovering devices: 'FTMSDeviceSimulator' object has no attribute 'discover_devices'
2025-04-27 13:04:11,743 - ftms - ERROR - Error discovering devices: 'FTMSDeviceSimulator' object has no attribute 'discover_devices'
2025-04-27 13:04:11,954 - ftms - ERROR - Error discovering devices: 'FTMSDeviceSimulator' object has no attribute 'discover_devices'
2025-04-27 13:04:13,181 - ftms - ERROR - Error discovering devices: 'FTMSDeviceSimulator' object has no attribute 'discover_devices'
2025-04-27 13:04:16,748 - ftms - ERROR - Error discovering devices: 'FTMSDeviceSimulator' object has no attribute 'discover_devices'
2025-04-27 13:04:16,959 - ftms - ERROR - Error discovering devices: 'FTMSDeviceSimulator' object has no attribute 'discover_devices'
2025-04-27 13:04:21,749 - ftms - ERROR - Error discovering devices: 'FTMSDeviceSimulator' object has no attribute 'discover_devices'
2025-04-27 13:04:21,959 - ftms - ERROR - Error discovering devices: 'FTMSDeviceSimulator' object has no attribute 'discover_devices'
2025-04-27 13:04:26,750 - ftms - ERROR - Error discovering devices: 'FTMSDeviceSimulator' object has no attribute 'discover_devices'
2025-04-27 13:04:26,962 - ftms - ERROR - Error discovering devices: 'FTMSDeviceSimulator' object has no attribute 'discover_devices'
2025-04-27 13:04:31,751 - ftms - ERROR - Error discovering devices: 'FTMSDeviceSimulator' object has no attribute 'discover_devices'
2025-04-27 13:04:31,963 - ftms - ERROR - Error discovering devices: 'FTMSDeviceSimulator' object has no attribute 'discover_devices'
2025-04-27 13:04:36,752 - ftms - ERROR - Error discovering devices: 'FTMSDeviceSimulator' object has no attribute 'discover_devices'
2025-04-27 13:04:36,964 - ftms - ERROR - Error discovering devices: 'FTMSDeviceSimulator' object has no attribute 'discover_devices'
2025-04-27 13:04:41,753 - ftms - ERROR - Error discovering devices: 'FTMSDeviceSimulator' object has no attribute 'discover_devices'
2025-04-27 13:04:41,965 - ftms - ERROR - Error discovering devices: 'FTMSDeviceSimulator' object has no attribute 'discover_devices'
2025-04-27 13:04:43,857 - ftms - ERROR - Error discovering devices: 'FTMSDeviceSimulator' object has no attribute 'discover_devices'
2025-04-27 13:04:46,754 - ftms - ERROR - Error discovering devices: 'FTMSDeviceSimulator' object has no attribute 'discover_devices'
2025-04-27 13:06:34,626 - ftms - ERROR - Error discovering devices: 'FTMSDeviceSimulator' object has no attribute 'discover_devices'
2025-04-27 13:06:34,833 - ftms - ERROR - Error discovering devices: 'FTMSDeviceSimulator' object has no attribute 'discover_devices'
2025-04-27 13:06:39,627 - ftms - ERROR - Error discovering devices: 'FTMSDeviceSimulator' object has no attribute 'discover_devices'
2025-04-27 13:06:39,836 - ftms - ERROR - Error discovering devices: 'FTMSDeviceSimulator' object has no attribute 'discover_devices'
2025-04-27 13:06:43,780 - ftms - ERROR - Error discovering devices: 'FTMSDeviceSimulator' object has no attribute 'discover_devices'
2025-04-27 13:06:44,628 - ftms - ERROR - Error discovering devices: 'FTMSDeviceSimulator' object has no attribute 'discover_devices'
2025-04-27 13:06:44,838 - ftms - ERROR - Error discovering devices: 'FTMSDeviceSimulator' object has no attribute 'discover_devices'
2025-04-27 13:06:48,072 - ftms - ERROR - Error discovering devices: 'FTMSDeviceSimulator' object has no attribute 'discover_devices'
2025-04-27 13:06:49,629 - ftms - ERROR - Error discovering devices: 'FTMSDeviceSimulator' object has no attribute 'discover_devices'
2025-04-27 13:06:49,839 - ftms - ERROR - Error discovering devices: 'FTMSDeviceSimulator' object has no attribute 'discover_devices'
2025-04-27 13:06:50,390 - ftms - ERROR - Error discovering devices: 'FTMSDeviceSimulator' object has no attribute 'discover_devices'
2025-04-27 13:06:54,630 - ftms - ERROR - Error discovering devices: 'FTMSDeviceSimulator' object has no attribute 'discover_devices'
2025-04-27 13:06:54,840 - ftms - ERROR - Error discovering devices: 'FTMSDeviceSimulator' object has no attribute 'discover_devices'
2025-04-27 13:11:51,028 - web - ERROR - Error discovering devices: Object of type SimulatedBLEDevice is not JSON serializable
2025-04-27 16:50:54,212 - web - ERROR - Error discovering devices: Object of type BLEDevice is not JSON serializable
2025-04-27 16:51:02,577 - web - ERROR - Error discovering devices: Object of type BLEDevice is not JSON serializable
2025-04-27 16:56:03,127 - web - ERROR - Error discovering devices: 'str' object has no attribute 'name'
2025-04-27 17:05:38,417 - web - ERROR - Error connecting to device: 'FTMSDeviceManager' object has no attribute 'connect'
2025-04-27 17:09:09,055 - web - ERROR - Error connecting to device: name 'asyncio' is not defined
Traceback (most recent call last):
  File "C:\Users\dougl\rogue_garmin_bridge\src\web\app.py", line 212, in connect_device
    success = asyncio.run(ftms_manager.connect(device_address))
              ^^^^^^^
NameError: name 'asyncio' is not defined. Did you forget to import 'asyncio'
2025-04-27 17:10:12,123 - ftms_connector - ERROR - Error initializing FTMS service: 'FitnessMachineService' object has no attribute 'enable_notifications'
2025-04-27 17:10:15,562 - ftms - ERROR - Failed to connect to device C9:02:CB:68:17:C1
2025-04-27 17:10:24,806 - ftms_connector - ERROR - Error initializing FTMS service: 'FitnessMachineService' object has no attribute 'enable_notifications'
2025-04-27 17:10:30,162 - ftms - ERROR - Connection attempt timed out after 15 seconds
2025-04-27 17:10:33,725 - ftms - ERROR - Connection attempt timed out after 15 seconds
2025-04-27 17:12:58,302 - ftms_connector - ERROR - Error initializing FTMS service: 'FitnessMachineService' object has no attribute 'enable_notifications'
2025-04-27 17:13:01,636 - ftms - ERROR - Failed to connect to device C9:02:CB:68:17:C1
2025-04-27 17:15:30,766 - ftms_connector - ERROR - Error connecting to device after maximum retries: 'NoneType' object has no attribute 'bluetooth_address'
2025-04-27 17:15:30,768 - ftms - ERROR - Failed to connect to device C9:02:CB:68:17:C1
2025-04-27 17:16:58,842 - ftms - ERROR - Connection attempt timed out after 15 seconds
2025-04-27 17:17:01,784 - ftms - ERROR - Connection attempt timed out after 15 seconds
2025-04-27 17:18:20,065 - ftms_connector - ERROR - Error initializing FTMS service: 'FitnessMachineService' object has no attribute 'set_rower_data_handler'
2025-04-27 17:18:23,426 - ftms - ERROR - Failed to connect to device C9:02:CB:68:17:C1
2025-04-27 17:20:23,079 - workout_manager - ERROR - Cannot start workout: No device ID provided
2025-04-27 17:20:29,788 - workout_manager - ERROR - Cannot start workout: No device ID provided
2025-04-27 17:20:51,877 - workout_manager - ERROR - Cannot start workout: No device ID provided
2025-04-27 17:20:51,954 - workout_manager - ERROR - Cannot start workout: No device ID provided
2025-04-27 17:20:52,206 - workout_manager - ERROR - Cannot start workout: No device ID provided
2025-04-27 17:20:52,405 - workout_manager - ERROR - Cannot start workout: No device ID provided
2025-04-27 17:20:52,559 - workout_manager - ERROR - Cannot start workout: No device ID provided
2025-04-27 17:20:52,591 - workout_manager - ERROR - Cannot start workout: No device ID provided
2025-04-27 17:21:07,873 - workout_manager - ERROR - Cannot start workout: No device ID provided
2025-04-27 17:21:08,198 - workout_manager - ERROR - Cannot start workout: No device ID provided
2025-04-27 17:21:08,291 - workout_manager - ERROR - Cannot start workout: No device ID provided
2025-04-27 17:38:22,317 - ftms - ERROR - Connection attempt timed out after 15 seconds
2025-04-27 17:47:48,941 - workout_manager - ERROR - Error starting workout: Database.start_workout() got an unexpected keyword argument 'start_time'
2025-04-27 17:47:54,951 - workout_manager - ERROR - Error starting workout: Database.start_workout() got an unexpected keyword argument 'start_time'
2025-04-27 17:54:41,383 - web - ERROR - Error ending workout: WorkoutManager.end_workout() takes 1 positional argument but 2 were given
2025-04-27 18:02:38,531 - workout_manager - ERROR - Error ending workout: 'WorkoutManager' object has no attribute 'fit_converter'
2025-04-27 18:02:51,591 - workout_manager - ERROR - Error ending workout: 'WorkoutManager' object has no attribute 'fit_converter'
2025-04-27 18:07:05,617 - ftms_connector - ERROR - Error during disconnect: 'NoneType' object is not iterable
2025-04-27 18:07:08,262 - ftms - ERROR - Connection attempt timed out after 15 seconds
2025-04-27 18:07:08,372 - ftms - ERROR - Connection attempt timed out after 15 seconds
2025-04-27 18:07:08,409 - ftms - ERROR - Connection attempt timed out after 15 seconds
2025-04-27 18:07:08,411 - ftms - ERROR - Connection attempt timed out after 15 seconds
2025-04-27 18:07:08,684 - ftms - ERROR - Connection attempt timed out after 15 seconds
2025-04-27 18:17:46,202 - ftms_connector - ERROR - Error initializing FTMS service: 'FitnessMachineService' object has no attribute 'enable_notifications'
2025-04-27 18:17:49,592 - ftms - ERROR - Failed to connect to device C9:02:CB:68:17:C1
2025-04-27 18:18:03,969 - ftms_connector - ERROR - Error initializing FTMS service: 'FitnessMachineService' object has no attribute 'enable_notifications'
2025-04-27 18:18:07,210 - ftms - ERROR - Failed to connect to device C9:02:CB:68:17:C1
2025-04-27 18:18:15,976 - ftms_connector - ERROR - Error initializing FTMS service: 'FitnessMachineService' object has no attribute 'enable_notifications'
2025-04-27 18:18:19,308 - ftms - ERROR - Failed to connect to device C9:02:CB:68:17:C1
2025-04-27 18:18:42,493 - ftms_connector - ERROR - Error initializing FTMS service: 'FitnessMachineService' object has no attribute 'enable_notifications'
2025-04-27 18:18:45,795 - ftms - ERROR - Failed to connect to device C9:02:CB:68:17:C1
2025-04-27 18:18:55,409 - ftms_connector - ERROR - Error initializing FTMS service: 'FitnessMachineService' object has no attribute 'enable_notifications'
2025-04-27 18:18:58,710 - ftms - ERROR - Failed to connect to device C9:02:CB:68:17:C1
2025-04-27 18:19:20,203 - ftms_connector - ERROR - Error initializing FTMS service: 'FitnessMachineService' object has no attribute 'enable_notifications'
2025-04-27 18:19:23,505 - ftms - ERROR - Failed to connect to device C9:02:CB:68:17:C1
2025-04-27 18:51:03,560 - ftms_connector - ERROR - Error initializing FTMS service or enabling notifications: 'FitnessMachineService' object has no attribute 'set_rower_data_handler'
2025-04-27 18:51:06,807 - ftms - ERROR - Failed to connect to device C9:02:CB:68:17:C1
2025-04-27 18:51:21,776 - ftms_connector - ERROR - Error initializing FTMS service or enabling notifications: 'FitnessMachineService' object has no attribute 'set_rower_data_handler'
2025-04-27 18:51:25,055 - ftms - ERROR - Failed to connect to device C9:02:CB:68:17:C1
2025-04-27 18:53:54,325 - ftms_connector - ERROR - Error initializing FTMS service or enabling notifications: 'FitnessMachineService' object has no attribute 'set_rower_data_handler'
2025-04-27 18:53:57,692 - ftms - ERROR - Failed to connect to device C9:02:CB:68:17:C1
2025-04-27 18:54:05,787 - ftms_connector - ERROR - Error initializing FTMS service or enabling notifications: 'FitnessMachineService' object has no attribute 'set_rower_data_handler'
2025-04-27 18:54:09,034 - ftms - ERROR - Failed to connect to device C9:02:CB:68:17:C1
2025-04-27 18:54:21,242 - ftms_connector - ERROR - Error initializing FTMS service or enabling notifications: 'FitnessMachineService' object has no attribute 'set_rower_data_handler'
2025-04-27 18:54:24,546 - ftms - ERROR - Failed to connect to device C9:02:CB:68:17:C1
2025-04-27 18:56:16,459 - ftms_connector - ERROR - Error initializing FTMS service or enabling notifications: 'FitnessMachineService' object has no attribute 'set_rower_data_handler'
2025-04-27 18:56:19,612 - ftms - ERROR - Failed to connect to device C9:02:CB:68:17:C1
2025-04-27 19:17:31,884 - ftms - ERROR - Connection attempt timed out after 15 seconds
2025-04-27 19:20:05,987 - ftms_connector - ERROR - Error initializing FTMS service or enabling notifications: 'FitnessMachineService' object has no attribute 'set_rower_data_handler'
2025-04-27 19:20:09,173 - ftms - ERROR - Failed to connect to device C9:02:CB:68:17:C1
2025-04-27 19:26:39,812 - web - ERROR - Asyncio background loop is not running.
2025-04-27 19:27:51,733 - web - ERROR - Asyncio background loop is not running.
2025-04-27 19:27:56,278 - web - ERROR - Asyncio background loop is not running.
2025-04-27 19:29:01,782 - web - ERROR - Error discovering devices: A coroutine object is required
Traceback (most recent call last):
  File "C:\Users\dougl\rogue_garmin_bridge\src\web\app.py", line 123, in discover_devices
    future = asyncio.run_coroutine_threadsafe(ftms_manager.discover_devices(), background_loop)
             ^^^^^^^^^^^^^^^^^^^^^^^^^^^^^^^^^^^^^^^^^^^^^^^^^^^^^^^^^^^^^^^^^^^^^^^^^^^^^^^^^^
  File "C:\Users\dougl\AppData\Local\Programs\Python\Python312\Lib\asyncio\tasks.py", line 937, in run_coroutine_threadsafe
    raise TypeError('A coroutine object is required')
TypeError: A coroutine object is required
2025-04-27 19:29:09,279 - web - ERROR - Error discovering devices: A coroutine object is required
Traceback (most recent call last):
  File "C:\Users\dougl\rogue_garmin_bridge\src\web\app.py", line 123, in discover_devices
    future = asyncio.run_coroutine_threadsafe(ftms_manager.discover_devices(), background_loop)
             ^^^^^^^^^^^^^^^^^^^^^^^^^^^^^^^^^^^^^^^^^^^^^^^^^^^^^^^^^^^^^^^^^^^^^^^^^^^^^^^^^^
  File "C:\Users\dougl\AppData\Local\Programs\Python\Python312\Lib\asyncio\tasks.py", line 937, in run_coroutine_threadsafe
    raise TypeError('A coroutine object is required')
TypeError: A coroutine object is required
2025-04-27 19:29:30,042 - web - ERROR - Error discovering devices: A coroutine object is required
Traceback (most recent call last):
  File "C:\Users\dougl\rogue_garmin_bridge\src\web\app.py", line 123, in discover_devices
    future = asyncio.run_coroutine_threadsafe(ftms_manager.discover_devices(), background_loop)
             ^^^^^^^^^^^^^^^^^^^^^^^^^^^^^^^^^^^^^^^^^^^^^^^^^^^^^^^^^^^^^^^^^^^^^^^^^^^^^^^^^^
  File "C:\Users\dougl\AppData\Local\Programs\Python\Python312\Lib\asyncio\tasks.py", line 937, in run_coroutine_threadsafe
    raise TypeError('A coroutine object is required')
TypeError: A coroutine object is required
2025-04-27 19:31:08,456 - ftms_connector - ERROR - Error processing indoor bike data: 'IndoorBikeData' object has no attribute 'get'
Traceback (most recent call last):
  File "C:\Users\dougl\rogue_garmin_bridge\src\ftms\ftms_connector.py", line 407, in _handle_indoor_bike_data
    'timestamp': data.get('elapsed_time', 0),
                ^^^^^^^^
AttributeError: 'IndoorBikeData' object has no attribute 'get'
2025-04-27 19:31:09,387 - ftms_connector - ERROR - Error processing indoor bike data: 'IndoorBikeData' object has no attribute 'get'
Traceback (most recent call last):
  File "C:\Users\dougl\rogue_garmin_bridge\src\ftms\ftms_connector.py", line 407, in _handle_indoor_bike_data
    'timestamp': data.get('elapsed_time', 0),
                ^^^^^^^^
AttributeError: 'IndoorBikeData' object has no attribute 'get'
2025-04-27 19:31:10,376 - ftms_connector - ERROR - Error processing indoor bike data: 'IndoorBikeData' object has no attribute 'get'
Traceback (most recent call last):
  File "C:\Users\dougl\rogue_garmin_bridge\src\ftms\ftms_connector.py", line 407, in _handle_indoor_bike_data
    'timestamp': data.get('elapsed_time', 0),
                ^^^^^^^^
AttributeError: 'IndoorBikeData' object has no attribute 'get'
2025-04-27 19:31:11,396 - ftms_connector - ERROR - Error processing indoor bike data: 'IndoorBikeData' object has no attribute 'get'
Traceback (most recent call last):
  File "C:\Users\dougl\rogue_garmin_bridge\src\ftms\ftms_connector.py", line 407, in _handle_indoor_bike_data
    'timestamp': data.get('elapsed_time', 0),
                ^^^^^^^^
AttributeError: 'IndoorBikeData' object has no attribute 'get'
2025-04-27 19:31:12,387 - ftms_connector - ERROR - Error processing indoor bike data: 'IndoorBikeData' object has no attribute 'get'
Traceback (most recent call last):
  File "C:\Users\dougl\rogue_garmin_bridge\src\ftms\ftms_connector.py", line 407, in _handle_indoor_bike_data
    'timestamp': data.get('elapsed_time', 0),
                ^^^^^^^^
AttributeError: 'IndoorBikeData' object has no attribute 'get'
2025-04-27 19:31:13,426 - ftms_connector - ERROR - Error processing indoor bike data: 'IndoorBikeData' object has no attribute 'get'
Traceback (most recent call last):
  File "C:\Users\dougl\rogue_garmin_bridge\src\ftms\ftms_connector.py", line 407, in _handle_indoor_bike_data
    'timestamp': data.get('elapsed_time', 0),
                ^^^^^^^^
AttributeError: 'IndoorBikeData' object has no attribute 'get'
2025-04-27 19:31:14,397 - ftms_connector - ERROR - Error processing indoor bike data: 'IndoorBikeData' object has no attribute 'get'
Traceback (most recent call last):
  File "C:\Users\dougl\rogue_garmin_bridge\src\ftms\ftms_connector.py", line 407, in _handle_indoor_bike_data
    'timestamp': data.get('elapsed_time', 0),
                ^^^^^^^^
AttributeError: 'IndoorBikeData' object has no attribute 'get'
2025-04-27 19:31:15,418 - ftms_connector - ERROR - Error processing indoor bike data: 'IndoorBikeData' object has no attribute 'get'
Traceback (most recent call last):
  File "C:\Users\dougl\rogue_garmin_bridge\src\ftms\ftms_connector.py", line 407, in _handle_indoor_bike_data
    'timestamp': data.get('elapsed_time', 0),
                ^^^^^^^^
AttributeError: 'IndoorBikeData' object has no attribute 'get'
2025-04-27 19:31:16,378 - ftms_connector - ERROR - Error processing indoor bike data: 'IndoorBikeData' object has no attribute 'get'
Traceback (most recent call last):
  File "C:\Users\dougl\rogue_garmin_bridge\src\ftms\ftms_connector.py", line 407, in _handle_indoor_bike_data
    'timestamp': data.get('elapsed_time', 0),
                ^^^^^^^^
AttributeError: 'IndoorBikeData' object has no attribute 'get'
2025-04-27 19:31:17,397 - ftms_connector - ERROR - Error processing indoor bike data: 'IndoorBikeData' object has no attribute 'get'
Traceback (most recent call last):
  File "C:\Users\dougl\rogue_garmin_bridge\src\ftms\ftms_connector.py", line 407, in _handle_indoor_bike_data
    'timestamp': data.get('elapsed_time', 0),
                ^^^^^^^^
AttributeError: 'IndoorBikeData' object has no attribute 'get'
2025-04-27 19:31:18,417 - ftms_connector - ERROR - Error processing indoor bike data: 'IndoorBikeData' object has no attribute 'get'
Traceback (most recent call last):
  File "C:\Users\dougl\rogue_garmin_bridge\src\ftms\ftms_connector.py", line 407, in _handle_indoor_bike_data
    'timestamp': data.get('elapsed_time', 0),
                ^^^^^^^^
AttributeError: 'IndoorBikeData' object has no attribute 'get'
2025-04-27 19:31:19,377 - ftms_connector - ERROR - Error processing indoor bike data: 'IndoorBikeData' object has no attribute 'get'
Traceback (most recent call last):
  File "C:\Users\dougl\rogue_garmin_bridge\src\ftms\ftms_connector.py", line 407, in _handle_indoor_bike_data
    'timestamp': data.get('elapsed_time', 0),
                ^^^^^^^^
AttributeError: 'IndoorBikeData' object has no attribute 'get'
2025-04-27 19:31:20,427 - ftms_connector - ERROR - Error processing indoor bike data: 'IndoorBikeData' object has no attribute 'get'
Traceback (most recent call last):
  File "C:\Users\dougl\rogue_garmin_bridge\src\ftms\ftms_connector.py", line 407, in _handle_indoor_bike_data
    'timestamp': data.get('elapsed_time', 0),
                ^^^^^^^^
AttributeError: 'IndoorBikeData' object has no attribute 'get'
2025-04-27 19:31:21,387 - ftms_connector - ERROR - Error processing indoor bike data: 'IndoorBikeData' object has no attribute 'get'
Traceback (most recent call last):
  File "C:\Users\dougl\rogue_garmin_bridge\src\ftms\ftms_connector.py", line 407, in _handle_indoor_bike_data
    'timestamp': data.get('elapsed_time', 0),
                ^^^^^^^^
AttributeError: 'IndoorBikeData' object has no attribute 'get'
2025-04-27 19:31:22,408 - ftms_connector - ERROR - Error processing indoor bike data: 'IndoorBikeData' object has no attribute 'get'
Traceback (most recent call last):
  File "C:\Users\dougl\rogue_garmin_bridge\src\ftms\ftms_connector.py", line 407, in _handle_indoor_bike_data
    'timestamp': data.get('elapsed_time', 0),
                ^^^^^^^^
AttributeError: 'IndoorBikeData' object has no attribute 'get'
2025-04-27 19:31:23,397 - ftms_connector - ERROR - Error processing indoor bike data: 'IndoorBikeData' object has no attribute 'get'
Traceback (most recent call last):
  File "C:\Users\dougl\rogue_garmin_bridge\src\ftms\ftms_connector.py", line 407, in _handle_indoor_bike_data
    'timestamp': data.get('elapsed_time', 0),
                ^^^^^^^^
AttributeError: 'IndoorBikeData' object has no attribute 'get'
2025-04-27 19:31:24,388 - ftms_connector - ERROR - Error processing indoor bike data: 'IndoorBikeData' object has no attribute 'get'
Traceback (most recent call last):
  File "C:\Users\dougl\rogue_garmin_bridge\src\ftms\ftms_connector.py", line 407, in _handle_indoor_bike_data
    'timestamp': data.get('elapsed_time', 0),
                ^^^^^^^^
AttributeError: 'IndoorBikeData' object has no attribute 'get'
2025-04-27 19:31:25,406 - ftms_connector - ERROR - Error processing indoor bike data: 'IndoorBikeData' object has no attribute 'get'
Traceback (most recent call last):
  File "C:\Users\dougl\rogue_garmin_bridge\src\ftms\ftms_connector.py", line 407, in _handle_indoor_bike_data
    'timestamp': data.get('elapsed_time', 0),
                ^^^^^^^^
AttributeError: 'IndoorBikeData' object has no attribute 'get'
2025-04-27 19:31:26,397 - ftms_connector - ERROR - Error processing indoor bike data: 'IndoorBikeData' object has no attribute 'get'
Traceback (most recent call last):
  File "C:\Users\dougl\rogue_garmin_bridge\src\ftms\ftms_connector.py", line 407, in _handle_indoor_bike_data
    'timestamp': data.get('elapsed_time', 0),
                ^^^^^^^^
AttributeError: 'IndoorBikeData' object has no attribute 'get'
2025-04-27 19:31:27,388 - ftms_connector - ERROR - Error processing indoor bike data: 'IndoorBikeData' object has no attribute 'get'
Traceback (most recent call last):
  File "C:\Users\dougl\rogue_garmin_bridge\src\ftms\ftms_connector.py", line 407, in _handle_indoor_bike_data
    'timestamp': data.get('elapsed_time', 0),
                ^^^^^^^^
AttributeError: 'IndoorBikeData' object has no attribute 'get'
2025-04-27 19:31:28,424 - ftms_connector - ERROR - Error processing indoor bike data: 'IndoorBikeData' object has no attribute 'get'
Traceback (most recent call last):
  File "C:\Users\dougl\rogue_garmin_bridge\src\ftms\ftms_connector.py", line 407, in _handle_indoor_bike_data
    'timestamp': data.get('elapsed_time', 0),
                ^^^^^^^^
AttributeError: 'IndoorBikeData' object has no attribute 'get'
2025-04-27 19:31:29,398 - ftms_connector - ERROR - Error processing indoor bike data: 'IndoorBikeData' object has no attribute 'get'
Traceback (most recent call last):
  File "C:\Users\dougl\rogue_garmin_bridge\src\ftms\ftms_connector.py", line 407, in _handle_indoor_bike_data
    'timestamp': data.get('elapsed_time', 0),
                ^^^^^^^^
AttributeError: 'IndoorBikeData' object has no attribute 'get'
2025-04-27 19:31:30,448 - ftms_connector - ERROR - Error processing indoor bike data: 'IndoorBikeData' object has no attribute 'get'
Traceback (most recent call last):
  File "C:\Users\dougl\rogue_garmin_bridge\src\ftms\ftms_connector.py", line 407, in _handle_indoor_bike_data
    'timestamp': data.get('elapsed_time', 0),
                ^^^^^^^^
AttributeError: 'IndoorBikeData' object has no attribute 'get'
2025-04-27 19:31:31,378 - ftms_connector - ERROR - Error processing indoor bike data: 'IndoorBikeData' object has no attribute 'get'
Traceback (most recent call last):
  File "C:\Users\dougl\rogue_garmin_bridge\src\ftms\ftms_connector.py", line 407, in _handle_indoor_bike_data
    'timestamp': data.get('elapsed_time', 0),
                ^^^^^^^^
AttributeError: 'IndoorBikeData' object has no attribute 'get'
2025-04-27 19:31:32,505 - ftms_connector - ERROR - Error processing indoor bike data: 'IndoorBikeData' object has no attribute 'get'
Traceback (most recent call last):
  File "C:\Users\dougl\rogue_garmin_bridge\src\ftms\ftms_connector.py", line 407, in _handle_indoor_bike_data
    'timestamp': data.get('elapsed_time', 0),
                ^^^^^^^^
AttributeError: 'IndoorBikeData' object has no attribute 'get'
2025-04-27 19:31:33,448 - ftms_connector - ERROR - Error processing indoor bike data: 'IndoorBikeData' object has no attribute 'get'
Traceback (most recent call last):
  File "C:\Users\dougl\rogue_garmin_bridge\src\ftms\ftms_connector.py", line 407, in _handle_indoor_bike_data
    'timestamp': data.get('elapsed_time', 0),
                ^^^^^^^^
AttributeError: 'IndoorBikeData' object has no attribute 'get'
2025-04-29 19:45:49,626 - web - ERROR - Error getting workout summary: 'WorkoutManager' object has no attribute 'get_workout_summary_metrics'
2025-04-29 19:45:49,685 - web - ERROR - Error getting workout summary: 'WorkoutManager' object has no attribute 'get_workout_summary_metrics'
2025-04-29 19:45:50,377 - web - ERROR - Error getting workout summary: 'WorkoutManager' object has no attribute 'get_workout_summary_metrics'
2025-04-29 19:45:51,704 - web - ERROR - Error getting workout summary: 'WorkoutManager' object has no attribute 'get_workout_summary_metrics'
2025-04-29 19:45:52,386 - web - ERROR - Error getting workout summary: 'WorkoutManager' object has no attribute 'get_workout_summary_metrics'
2025-04-29 19:45:53,693 - web - ERROR - Error getting workout summary: 'WorkoutManager' object has no attribute 'get_workout_summary_metrics'
2025-04-29 19:45:54,391 - web - ERROR - Error getting workout summary: 'WorkoutManager' object has no attribute 'get_workout_summary_metrics'
2025-04-29 19:45:55,708 - web - ERROR - Error getting workout summary: 'WorkoutManager' object has no attribute 'get_workout_summary_metrics'
2025-04-29 19:45:56,379 - web - ERROR - Error getting workout summary: 'WorkoutManager' object has no attribute 'get_workout_summary_metrics'
2025-04-29 19:45:57,697 - web - ERROR - Error getting workout summary: 'WorkoutManager' object has no attribute 'get_workout_summary_metrics'
2025-04-29 19:45:58,386 - web - ERROR - Error getting workout summary: 'WorkoutManager' object has no attribute 'get_workout_summary_metrics'
2025-04-29 19:45:59,698 - web - ERROR - Error getting workout summary: 'WorkoutManager' object has no attribute 'get_workout_summary_metrics'
2025-04-29 19:46:00,382 - web - ERROR - Error getting workout summary: 'WorkoutManager' object has no attribute 'get_workout_summary_metrics'
2025-04-29 19:46:01,689 - web - ERROR - Error getting workout summary: 'WorkoutManager' object has no attribute 'get_workout_summary_metrics'
2025-04-29 19:46:02,393 - web - ERROR - Error getting workout summary: 'WorkoutManager' object has no attribute 'get_workout_summary_metrics'
2025-04-29 19:46:03,704 - web - ERROR - Error getting workout summary: 'WorkoutManager' object has no attribute 'get_workout_summary_metrics'
2025-04-29 19:46:04,382 - web - ERROR - Error getting workout summary: 'WorkoutManager' object has no attribute 'get_workout_summary_metrics'
2025-04-29 19:46:05,684 - web - ERROR - Error getting workout summary: 'WorkoutManager' object has no attribute 'get_workout_summary_metrics'
2025-04-29 19:46:06,380 - web - ERROR - Error getting workout summary: 'WorkoutManager' object has no attribute 'get_workout_summary_metrics'
2025-04-29 19:46:07,696 - web - ERROR - Error getting workout summary: 'WorkoutManager' object has no attribute 'get_workout_summary_metrics'
2025-04-29 19:46:13,570 - web - ERROR - Error getting workout summary: 'WorkoutManager' object has no attribute 'get_workout_summary_metrics'
2025-04-29 19:46:13,830 - web - ERROR - Error getting workout summary: 'WorkoutManager' object has no attribute 'get_workout_summary_metrics'
2025-04-29 19:46:14,527 - web - ERROR - Error getting workout summary: 'WorkoutManager' object has no attribute 'get_workout_summary_metrics'
2025-04-29 19:46:15,834 - web - ERROR - Error getting workout summary: 'WorkoutManager' object has no attribute 'get_workout_summary_metrics'
2025-04-29 19:46:16,526 - web - ERROR - Error getting workout summary: 'WorkoutManager' object has no attribute 'get_workout_summary_metrics'
2025-04-29 19:46:17,849 - web - ERROR - Error getting workout summary: 'WorkoutManager' object has no attribute 'get_workout_summary_metrics'
2025-04-29 19:46:18,531 - web - ERROR - Error getting workout summary: 'WorkoutManager' object has no attribute 'get_workout_summary_metrics'
2025-04-29 19:46:19,833 - web - ERROR - Error getting workout summary: 'WorkoutManager' object has no attribute 'get_workout_summary_metrics'
2025-04-29 19:46:20,534 - web - ERROR - Error getting workout summary: 'WorkoutManager' object has no attribute 'get_workout_summary_metrics'
2025-04-29 19:46:21,832 - web - ERROR - Error getting workout summary: 'WorkoutManager' object has no attribute 'get_workout_summary_metrics'
2025-04-29 19:46:22,532 - web - ERROR - Error getting workout summary: 'WorkoutManager' object has no attribute 'get_workout_summary_metrics'
2025-04-29 19:46:23,832 - web - ERROR - Error getting workout summary: 'WorkoutManager' object has no attribute 'get_workout_summary_metrics'
2025-04-29 19:46:24,519 - web - ERROR - Error getting workout summary: 'WorkoutManager' object has no attribute 'get_workout_summary_metrics'
2025-04-29 19:46:25,835 - web - ERROR - Error getting workout summary: 'WorkoutManager' object has no attribute 'get_workout_summary_metrics'
2025-04-29 19:50:25,420 - database - ERROR - Error adding workout data for workout 83, timestamp 0.681871: SQLite objects created in a thread can only be used in that same thread. The object was created in thread id 25448 and this is thread id 38576.
Traceback (most recent call last):
  File "C:\Users\dougl\rogue_garmin_bridge\src\data\database.py", line 347, in add_workout_data
    self.conn.commit()
sqlite3.ProgrammingError: SQLite objects created in a thread can only be used in that same thread. The object was created in thread id 25448 and this is thread id 38576.
2025-04-29 19:50:25,425 - workout_manager - ERROR - Failed to add data point to workout 83
2025-04-29 19:50:27,531 - ftms_connector - ERROR - AttributeError processing indoor bike data: 'NoneType' object has no attribute 'commit'. Data object: IndoorBikeData(instant_speed=12.55, average_speed=0.78, instant_cadence=21.0, average_cadence=21.0, total_distance=16, resistance_level=None, instant_power=18, average_power=18, total_energy=0, energy_per_hour=0, energy_per_minute=0, heart_rate=89, metabolic_equivalent=None, elapsed_time=6, remaining_time=None)
Traceback (most recent call last):
  File "C:\Users\dougl\rogue_garmin_bridge\src\ftms\ftms_connector.py", line 423, in _handle_indoor_bike_data
    callback(processed_data)
  File "C:\Users\dougl\rogue_garmin_bridge\src\ftms\ftms_manager.py", line 83, in _handle_data
    self._notify_data_callbacks(data)
  File "C:\Users\dougl\rogue_garmin_bridge\src\ftms\ftms_manager.py", line 90, in _notify_data_callbacks
    self._handle_ftms_data(data)
  File "C:\Users\dougl\rogue_garmin_bridge\src\ftms\ftms_manager.py", line 299, in _handle_ftms_data
    self.workout_manager.add_data_point(data)
  File "C:\Users\dougl\rogue_garmin_bridge\src\data\workout_manager.py", line 265, in add_data_point
    success = self.database.add_workout_data(
              ^^^^^^^^^^^^^^^^^^^^^^^^^^^^^^^
  File "C:\Users\dougl\rogue_garmin_bridge\src\data\database.py", line 347, in add_workout_data
    self.conn.commit()
    ^^^^^^^^^^^^^^^^
AttributeError: 'NoneType' object has no attribute 'commit'
2025-04-29 19:50:33,075 - database - ERROR - Error adding workout data for workout 83, timestamp 2.853219: database is locked
Traceback (most recent call last):
  File "C:\Users\dougl\rogue_garmin_bridge\src\data\database.py", line 339, in add_workout_data
    self.cursor.execute(
sqlite3.OperationalError: database is locked
2025-04-29 19:50:33,078 - workout_manager - ERROR - Failed to add data point to workout 83
2025-04-29 19:50:38,499 - database - ERROR - Error adding workout data for workout 83, timestamp 8.395774: database is locked
Traceback (most recent call last):
  File "C:\Users\dougl\rogue_garmin_bridge\src\data\database.py", line 339, in add_workout_data
    self.cursor.execute(
sqlite3.OperationalError: database is locked
2025-04-29 19:50:38,499 - workout_manager - ERROR - Failed to add data point to workout 83
2025-04-29 19:50:43,972 - database - ERROR - Error adding workout data for workout 83, timestamp 13.818413: database is locked
Traceback (most recent call last):
  File "C:\Users\dougl\rogue_garmin_bridge\src\data\database.py", line 339, in add_workout_data
    self.cursor.execute(
sqlite3.OperationalError: database is locked
2025-04-29 19:50:43,973 - workout_manager - ERROR - Failed to add data point to workout 83
2025-04-29 19:50:49,485 - database - ERROR - Error adding workout data for workout 83, timestamp 19.292214: database is locked
Traceback (most recent call last):
  File "C:\Users\dougl\rogue_garmin_bridge\src\data\database.py", line 339, in add_workout_data
    self.cursor.execute(
sqlite3.OperationalError: database is locked
2025-04-29 19:50:49,487 - workout_manager - ERROR - Failed to add data point to workout 83
2025-04-29 19:50:54,983 - database - ERROR - Error adding workout data for workout 83, timestamp 24.804143: database is locked
Traceback (most recent call last):
  File "C:\Users\dougl\rogue_garmin_bridge\src\data\database.py", line 339, in add_workout_data
    self.cursor.execute(
sqlite3.OperationalError: database is locked
2025-04-29 19:50:54,984 - workout_manager - ERROR - Failed to add data point to workout 83
2025-04-29 19:51:00,498 - database - ERROR - Error adding workout data for workout 83, timestamp 30.302045: database is locked
Traceback (most recent call last):
  File "C:\Users\dougl\rogue_garmin_bridge\src\data\database.py", line 339, in add_workout_data
    self.cursor.execute(
sqlite3.OperationalError: database is locked
2025-04-29 19:51:00,500 - workout_manager - ERROR - Failed to add data point to workout 83
2025-04-29 19:51:06,041 - database - ERROR - Error adding workout data for workout 83, timestamp 35.818930: database is locked
Traceback (most recent call last):
  File "C:\Users\dougl\rogue_garmin_bridge\src\data\database.py", line 339, in add_workout_data
    self.cursor.execute(
sqlite3.OperationalError: database is locked
2025-04-29 19:51:06,042 - workout_manager - ERROR - Failed to add data point to workout 83
2025-04-29 19:51:11,558 - database - ERROR - Error adding workout data for workout 83, timestamp 41.361323: database is locked
Traceback (most recent call last):
  File "C:\Users\dougl\rogue_garmin_bridge\src\data\database.py", line 339, in add_workout_data
    self.cursor.execute(
sqlite3.OperationalError: database is locked
2025-04-29 19:51:11,560 - workout_manager - ERROR - Failed to add data point to workout 83
2025-04-29 19:51:17,043 - database - ERROR - Error adding workout data for workout 83, timestamp 46.878251: database is locked
Traceback (most recent call last):
  File "C:\Users\dougl\rogue_garmin_bridge\src\data\database.py", line 339, in add_workout_data
    self.cursor.execute(
sqlite3.OperationalError: database is locked
2025-04-29 19:51:17,045 - workout_manager - ERROR - Failed to add data point to workout 83
2025-04-29 19:51:22,572 - database - ERROR - Error adding workout data for workout 83, timestamp 52.364046: database is locked
Traceback (most recent call last):
  File "C:\Users\dougl\rogue_garmin_bridge\src\data\database.py", line 339, in add_workout_data
    self.cursor.execute(
sqlite3.OperationalError: database is locked
2025-04-29 19:51:22,574 - workout_manager - ERROR - Failed to add data point to workout 83
2025-04-29 19:51:27,980 - database - ERROR - Error adding workout data for workout 83, timestamp 57.891984: database is locked
Traceback (most recent call last):
  File "C:\Users\dougl\rogue_garmin_bridge\src\data\database.py", line 339, in add_workout_data
    self.cursor.execute(
sqlite3.OperationalError: database is locked
2025-04-29 19:51:27,982 - workout_manager - ERROR - Failed to add data point to workout 83
2025-04-29 19:51:33,453 - database - ERROR - Error adding workout data for workout 83, timestamp 63.300150: database is locked
Traceback (most recent call last):
  File "C:\Users\dougl\rogue_garmin_bridge\src\data\database.py", line 339, in add_workout_data
    self.cursor.execute(
sqlite3.OperationalError: database is locked
2025-04-29 19:51:33,454 - workout_manager - ERROR - Failed to add data point to workout 83
2025-04-29 19:51:38,961 - database - ERROR - Error adding workout data for workout 83, timestamp 68.771712: database is locked
Traceback (most recent call last):
  File "C:\Users\dougl\rogue_garmin_bridge\src\data\database.py", line 339, in add_workout_data
    self.cursor.execute(
sqlite3.OperationalError: database is locked
2025-04-29 19:51:38,962 - workout_manager - ERROR - Failed to add data point to workout 83
2025-04-29 19:51:44,491 - database - ERROR - Error adding workout data for workout 83, timestamp 74.281098: database is locked
Traceback (most recent call last):
  File "C:\Users\dougl\rogue_garmin_bridge\src\data\database.py", line 339, in add_workout_data
    self.cursor.execute(
sqlite3.OperationalError: database is locked
2025-04-29 19:51:44,493 - workout_manager - ERROR - Failed to add data point to workout 83
2025-04-29 19:51:45,559 - database - ERROR - Error ending workout: database is locked
2025-04-29 19:51:45,560 - workout_manager - ERROR - Error ending workout: SQLite objects created in a thread can only be used in that same thread. The object was created in thread id 32724 and this is thread id 45376.
2025-04-29 19:51:47,286 - database - ERROR - Error ending workout: database is locked
2025-04-29 19:51:47,287 - workout_manager - ERROR - Error ending workout: SQLite objects created in a thread can only be used in that same thread. The object was created in thread id 32724 and this is thread id 40284.
2025-04-29 19:51:50,020 - database - ERROR - Error adding workout data for workout 83, timestamp 79.811638: database is locked
Traceback (most recent call last):
  File "C:\Users\dougl\rogue_garmin_bridge\src\data\database.py", line 339, in add_workout_data
    self.cursor.execute(
sqlite3.OperationalError: database is locked
2025-04-29 19:51:50,021 - workout_manager - ERROR - Failed to add data point to workout 83
2025-04-29 19:51:50,858 - database - ERROR - Error ending workout: database is locked
2025-04-29 19:51:50,859 - workout_manager - ERROR - Failed to update workout 83 in database
2025-04-29 19:51:51,088 - database - ERROR - Error ending workout: database is locked
2025-04-29 19:51:51,089 - workout_manager - ERROR - Failed to update workout 83 in database
2025-04-29 19:51:55,550 - database - ERROR - Error adding workout data for workout 83, timestamp 85.338522: database is locked
Traceback (most recent call last):
  File "C:\Users\dougl\rogue_garmin_bridge\src\data\database.py", line 339, in add_workout_data
    self.cursor.execute(
sqlite3.OperationalError: database is locked
2025-04-29 19:51:55,552 - workout_manager - ERROR - Failed to add data point to workout None
2025-04-29 20:10:50,575 - workout_manager - ERROR - Error deleting workout: 'Database' object has no attribute 'execute'
Traceback (most recent call last):
  File "C:\Users\dougl\rogue_garmin_bridge\src\data\workout_manager.py", line 716, in delete_workout
    data_deleted = self.database.execute(
                   ^^^^^^^^^^^^^^^^^^^^^
AttributeError: 'Database' object has no attribute 'execute'
2025-04-29 20:17:17,245 - database - ERROR - Error adding workout data for workout 85, timestamp 115.359895: SQLite objects created in a thread can only be used in that same thread. The object was created in thread id 22816 and this is thread id 44552.
Traceback (most recent call last):
  File "C:\Users\dougl\rogue_garmin_bridge\src\data\database.py", line 347, in add_workout_data
    self.conn.commit()
sqlite3.ProgrammingError: SQLite objects created in a thread can only be used in that same thread. The object was created in thread id 22816 and this is thread id 44552.
2025-04-29 20:17:17,250 - workout_manager - ERROR - Failed to add data point to workout 85
2025-04-29 20:17:23,513 - database - ERROR - Error adding workout data for workout 85, timestamp 116.172557: database is locked
Traceback (most recent call last):
  File "C:\Users\dougl\rogue_garmin_bridge\src\data\database.py", line 339, in add_workout_data
    self.cursor.execute(
sqlite3.OperationalError: database is locked
2025-04-29 20:17:23,515 - workout_manager - ERROR - Failed to add data point to workout 85
2025-04-29 20:17:27,222 - ftms_connector - ERROR - AttributeError processing indoor bike data: 'NoneType' object has no attribute 'commit'. Data object: IndoorBikeData(instant_speed=32.82, average_speed=1.96, instant_cadence=55.0, average_cadence=52.0, total_distance=1061, resistance_level=None, instant_power=194, average_power=166, total_energy=20, energy_per_hour=0, energy_per_minute=0, heart_rate=154, metabolic_equivalent=None, elapsed_time=122, remaining_time=None)
Traceback (most recent call last):
  File "C:\Users\dougl\rogue_garmin_bridge\src\ftms\ftms_connector.py", line 423, in _handle_indoor_bike_data
    callback(processed_data)
  File "C:\Users\dougl\rogue_garmin_bridge\src\ftms\ftms_manager.py", line 83, in _handle_data
    self._notify_data_callbacks(data)
  File "C:\Users\dougl\rogue_garmin_bridge\src\ftms\ftms_manager.py", line 90, in _notify_data_callbacks
    self._handle_ftms_data(data)
  File "C:\Users\dougl\rogue_garmin_bridge\src\ftms\ftms_manager.py", line 299, in _handle_ftms_data
    self.workout_manager.add_data_point(data)
  File "C:\Users\dougl\rogue_garmin_bridge\src\data\workout_manager.py", line 265, in add_data_point
    success = self.database.add_workout_data(
              ^^^^^^^^^^^^^^^^^^^^^^^^^^^^^^^
  File "C:\Users\dougl\rogue_garmin_bridge\src\data\database.py", line 347, in add_workout_data
    self.conn.commit()
    ^^^^^^^^^^^^^^^^
AttributeError: 'NoneType' object has no attribute 'commit'
2025-04-29 20:17:32,782 - database - ERROR - Error adding workout data for workout 85, timestamp 125.399231: database is locked
Traceback (most recent call last):
  File "C:\Users\dougl\rogue_garmin_bridge\src\data\database.py", line 339, in add_workout_data
    self.cursor.execute(
sqlite3.OperationalError: database is locked
2025-04-29 20:17:32,783 - database - ERROR - Error during rollback for workout 85: SQLite objects created in a thread can only be used in that same thread. The object was created in thread id 40716 and this is thread id 44552.
2025-04-29 20:17:32,783 - ftms_connector - ERROR - Error processing indoor bike data: SQLite objects created in a thread can only be used in that same thread. The object was created in thread id 40716 and this is thread id 44552.. Data object: IndoorBikeData(instant_speed=32.82, average_speed=1.96, instant_cadence=55.0, average_cadence=52.0, total_distance=1078, resistance_level=None, instant_power=194, average_power=166, total_energy=20, energy_per_hour=0, energy_per_minute=0, heart_rate=154, metabolic_equivalent=None, elapsed_time=123, remaining_time=None)
Traceback (most recent call last):
  File "C:\Users\dougl\rogue_garmin_bridge\src\ftms\ftms_connector.py", line 423, in _handle_indoor_bike_data
    callback(processed_data)
  File "C:\Users\dougl\rogue_garmin_bridge\src\ftms\ftms_manager.py", line 83, in _handle_data
    self._notify_data_callbacks(data)
  File "C:\Users\dougl\rogue_garmin_bridge\src\ftms\ftms_manager.py", line 90, in _notify_data_callbacks
    self._handle_ftms_data(data)
  File "C:\Users\dougl\rogue_garmin_bridge\src\ftms\ftms_manager.py", line 299, in _handle_ftms_data
    self.workout_manager.add_data_point(data)
  File "C:\Users\dougl\rogue_garmin_bridge\src\data\workout_manager.py", line 265, in add_data_point
    success = self.database.add_workout_data(
              ^^^^^^^^^^^^^^^^^^^^^^^^^^^^^^^
  File "C:\Users\dougl\rogue_garmin_bridge\src\data\database.py", line 361, in add_workout_data
    self._disconnect()
  File "C:\Users\dougl\rogue_garmin_bridge\src\data\database.py", line 61, in _disconnect
    self.conn.close()
sqlite3.ProgrammingError: SQLite objects created in a thread can only be used in that same thread. The object was created in thread id 40716 and this is thread id 44552.
2025-04-29 20:17:35,326 - database - ERROR - Error ending workout: database is locked
2025-04-29 20:17:35,328 - workout_manager - ERROR - Failed to update workout 85 in database
2025-04-29 20:17:38,262 - database - ERROR - Error ending workout: database is locked
2025-04-29 20:17:38,263 - workout_manager - ERROR - Failed to update workout 85 in database
2025-04-29 20:17:38,280 - database - ERROR - Error adding workout data for workout 85, timestamp 130.958976: database is locked
Traceback (most recent call last):
  File "C:\Users\dougl\rogue_garmin_bridge\src\data\database.py", line 339, in add_workout_data
    self.cursor.execute(
sqlite3.OperationalError: database is locked
2025-04-29 20:17:38,281 - workout_manager - ERROR - Failed to add data point to workout None
2025-04-29 20:49:17,906 - fit_converter - ERROR - Unsupported workout type: unknown
2025-04-29 20:49:18,152 - fit_converter - ERROR - Unsupported workout type: unknown
2025-04-29 20:49:30,226 - fit_converter - ERROR - Error converting bike workout to FIT: time_created encoded value -629319626 is not in valid range [0, 4294967295]
2025-04-29 21:05:13,532 - database - ERROR - Error adding workout data for workout 2, timestamp 0.231590: SQLite objects created in a thread can only be used in that same thread. The object was created in thread id 26600 and this is thread id 34136.
Traceback (most recent call last):
  File "C:\Users\dougl\rogue_garmin_bridge\src\data\database.py", line 347, in add_workout_data
    self.conn.commit()
sqlite3.ProgrammingError: SQLite objects created in a thread can only be used in that same thread. The object was created in thread id 26600 and this is thread id 34136.
2025-04-29 21:05:13,536 - workout_manager - ERROR - Failed to add data point to workout 2
2025-04-29 21:05:19,954 - database - ERROR - Error adding workout data for workout 2, timestamp 1.217360: database is locked
Traceback (most recent call last):
  File "C:\Users\dougl\rogue_garmin_bridge\src\data\database.py", line 339, in add_workout_data
    self.cursor.execute(
sqlite3.OperationalError: database is locked
2025-04-29 21:05:19,957 - workout_manager - ERROR - Failed to add data point to workout 2
2025-04-29 21:05:20,220 - ftms_connector - ERROR - AttributeError processing indoor bike data: 'NoneType' object has no attribute 'commit'. Data object: IndoorBikeData(instant_speed=14.96, average_speed=0.89, instant_cadence=25.0, average_cadence=24.0, total_distance=32, resistance_level=None, instant_power=28, average_power=25, total_energy=0, energy_per_hour=0, energy_per_minute=0, heart_rate=96, metabolic_equivalent=None, elapsed_time=11, remaining_time=None)
Traceback (most recent call last):
  File "C:\Users\dougl\rogue_garmin_bridge\src\ftms\ftms_connector.py", line 423, in _handle_indoor_bike_data
    callback(processed_data)
  File "C:\Users\dougl\rogue_garmin_bridge\src\ftms\ftms_manager.py", line 83, in _handle_data
    self._notify_data_callbacks(data)
  File "C:\Users\dougl\rogue_garmin_bridge\src\ftms\ftms_manager.py", line 90, in _notify_data_callbacks
    self._handle_ftms_data(data)
  File "C:\Users\dougl\rogue_garmin_bridge\src\ftms\ftms_manager.py", line 299, in _handle_ftms_data
    self.workout_manager.add_data_point(data)
  File "C:\Users\dougl\rogue_garmin_bridge\src\data\workout_manager.py", line 265, in add_data_point
    success = self.database.add_workout_data(
              ^^^^^^^^^^^^^^^^^^^^^^^^^^^^^^^
  File "C:\Users\dougl\rogue_garmin_bridge\src\data\database.py", line 347, in add_workout_data
    self.conn.commit()
    ^^^^^^^^^^^^^^^^
AttributeError: 'NoneType' object has no attribute 'commit'
2025-04-29 21:05:25,759 - database - ERROR - Error adding workout data for workout 2, timestamp 6.994592: database is locked
Traceback (most recent call last):
  File "C:\Users\dougl\rogue_garmin_bridge\src\data\database.py", line 339, in add_workout_data
    self.cursor.execute(
sqlite3.OperationalError: database is locked
2025-04-29 21:05:25,762 - workout_manager - ERROR - Failed to add data point to workout 2
2025-04-29 21:05:31,292 - database - ERROR - Error adding workout data for workout 2, timestamp 12.518916: database is locked
Traceback (most recent call last):
  File "C:\Users\dougl\rogue_garmin_bridge\src\data\database.py", line 339, in add_workout_data
    self.cursor.execute(
sqlite3.OperationalError: database is locked
2025-04-29 21:05:31,295 - workout_manager - ERROR - Failed to add data point to workout 2
2025-04-29 21:05:36,764 - database - ERROR - Error adding workout data for workout 2, timestamp 18.051172: database is locked
Traceback (most recent call last):
  File "C:\Users\dougl\rogue_garmin_bridge\src\data\database.py", line 339, in add_workout_data
    self.cursor.execute(
sqlite3.OperationalError: database is locked
2025-04-29 21:05:36,766 - workout_manager - ERROR - Failed to add data point to workout 2
2025-04-29 21:05:37,245 - database - ERROR - Error ending workout: database is locked
2025-04-29 21:05:37,246 - workout_manager - ERROR - Error ending workout: SQLite objects created in a thread can only be used in that same thread. The object was created in thread id 34136 and this is thread id 31396.
2025-04-29 21:05:42,266 - database - ERROR - Error adding workout data for workout 2, timestamp 23.522678: database is locked
Traceback (most recent call last):
  File "C:\Users\dougl\rogue_garmin_bridge\src\data\database.py", line 339, in add_workout_data
    self.cursor.execute(
sqlite3.OperationalError: database is locked
2025-04-29 21:05:42,268 - database - ERROR - Error during rollback for workout 2: SQLite objects created in a thread can only be used in that same thread. The object was created in thread id 35492 and this is thread id 34136.
2025-04-29 21:05:42,269 - ftms_connector - ERROR - Error processing indoor bike data: SQLite objects created in a thread can only be used in that same thread. The object was created in thread id 35492 and this is thread id 34136.. Data object: IndoorBikeData(instant_speed=14.96, average_speed=0.9, instant_cadence=25.0, average_cadence=24.0, total_distance=48, resistance_level=None, instant_power=28, average_power=25, total_energy=0, energy_per_hour=0, energy_per_minute=0, heart_rate=97, metabolic_equivalent=None, elapsed_time=15, remaining_time=None)
Traceback (most recent call last):
  File "C:\Users\dougl\rogue_garmin_bridge\src\ftms\ftms_connector.py", line 423, in _handle_indoor_bike_data
    callback(processed_data)
  File "C:\Users\dougl\rogue_garmin_bridge\src\ftms\ftms_manager.py", line 83, in _handle_data
    self._notify_data_callbacks(data)
  File "C:\Users\dougl\rogue_garmin_bridge\src\ftms\ftms_manager.py", line 90, in _notify_data_callbacks
    self._handle_ftms_data(data)
  File "C:\Users\dougl\rogue_garmin_bridge\src\ftms\ftms_manager.py", line 299, in _handle_ftms_data
    self.workout_manager.add_data_point(data)
  File "C:\Users\dougl\rogue_garmin_bridge\src\data\workout_manager.py", line 265, in add_data_point
    success = self.database.add_workout_data(
              ^^^^^^^^^^^^^^^^^^^^^^^^^^^^^^^
  File "C:\Users\dougl\rogue_garmin_bridge\src\data\database.py", line 361, in add_workout_data
    self._disconnect()
  File "C:\Users\dougl\rogue_garmin_bridge\src\data\database.py", line 61, in _disconnect
    self.conn.close()
sqlite3.ProgrammingError: SQLite objects created in a thread can only be used in that same thread. The object was created in thread id 35492 and this is thread id 34136.
2025-04-29 21:05:42,792 - database - ERROR - Error ending workout: database is locked
2025-04-29 21:05:42,794 - workout_manager - ERROR - Failed to update workout 2 in database
2025-04-29 21:05:47,081 - database - ERROR - Error ending workout: database is locked
2025-04-29 21:05:47,082 - workout_manager - ERROR - Failed to update workout 2 in database
2025-04-29 21:05:47,776 - database - ERROR - Error adding workout data for workout 2, timestamp 29.029523: database is locked
Traceback (most recent call last):
  File "C:\Users\dougl\rogue_garmin_bridge\src\data\database.py", line 339, in add_workout_data
    self.cursor.execute(
sqlite3.OperationalError: database is locked
2025-04-29 21:05:47,778 - workout_manager - ERROR - Failed to add data point to workout None
2025-04-29 21:40:40,449 - web - ERROR - Error getting workouts: 'Database' object has no attribute '_connect'
Traceback (most recent call last):
  File "C:\Users\dougl\rogue_garmin_bridge\src\web\app.py", line 376, in get_workouts
    db._connect()
    ^^^^^^^^^^^
AttributeError: 'Database' object has no attribute '_connect'
2025-04-29 21:54:39,639 - fit_converter - ERROR - Error converting bike workout to FIT: time_created encoded value -629319622 is not in valid range [0, 4294967295]
2025-04-29 22:04:47,839 - fit_converter - ERROR - Error converting bike workout to FIT: time_created encoded value -629319621 is not in valid range [0, 4294967295]
2025-04-29 22:04:47,840 - web - ERROR - FIT conversion returned None for workout 1
2025-04-29 22:13:24,703 - fit_converter - ERROR - Error converting bike workout to FIT: time_created encoded value -629319626 is not in valid range [0, 4294967295]
2025-04-29 22:13:24,703 - web - ERROR - FIT conversion returned None for workout 1
2025-04-29 22:13:45,469 - workout_manager - ERROR - Error deleting workout: 'Database' object has no attribute '_connect'
Traceback (most recent call last):
  File "C:\Users\dougl\rogue_garmin_bridge\src\data\workout_manager.py", line 717, in delete_workout
    self.database._connect()
    ^^^^^^^^^^^^^^^^^^^^^^
AttributeError: 'Database' object has no attribute '_connect'
2025-04-29 22:14:24,330 - fit_converter - ERROR - Error converting bike workout to FIT: time_created encoded value -629319624 is not in valid range [0, 4294967295]
2025-04-29 22:14:24,330 - web - ERROR - FIT conversion returned None for workout 4
2025-04-29 22:31:16,283 - fit_converter - ERROR - Error converting bike workout to FIT: time_created encoded value -629950708 is not in valid range [0, 4294967295]
2025-04-29 22:31:16,283 - web - ERROR - FIT conversion returned None for workout 4
2025-04-29 22:31:36,926 - fit_converter - ERROR - Error converting bike workout to FIT: time_created encoded value -629950708 is not in valid range [0, 4294967295]
2025-04-29 22:31:36,926 - web - ERROR - FIT conversion returned None for workout 4
2025-04-29 22:33:42,556 - fit_converter - ERROR - Error converting bike workout to FIT: time_created encoded value -629319620 is not in valid range [0, 4294967295]
2025-04-29 22:33:42,556 - web - ERROR - FIT conversion returned None for workout 4
2025-04-29 22:33:54,633 - fit_converter - ERROR - Error converting bike workout to FIT: time_created encoded value -629319620 is not in valid range [0, 4294967295]
2025-04-29 22:33:54,634 - web - ERROR - FIT conversion returned None for workout 1
2025-04-29 22:37:30,260 - fit_converter - ERROR - Error converting bike workout to FIT: time_created encoded value -629487702 is not in valid range [0, 4294967295]
2025-04-29 22:37:30,260 - web - ERROR - FIT conversion returned None for workout 1
2025-04-29 22:37:34,008 - fit_converter - ERROR - Error converting bike workout to FIT: time_created encoded value -629487702 is not in valid range [0, 4294967295]
2025-04-29 22:37:34,010 - web - ERROR - FIT conversion returned None for workout 1
2025-04-29 22:39:11,552 - fit_converter - ERROR - Error converting bike workout to FIT: time_created encoded value -630118915 is not in valid range [0, 4294967295]
2025-04-29 22:39:11,553 - web - ERROR - FIT conversion returned None for workout 1
2025-04-29 22:41:08,083 - fit_converter - ERROR - Error converting bike workout to FIT: time_created encoded value -630065600 is not in valid range [0, 4294967295]
2025-04-29 22:41:08,084 - web - ERROR - FIT conversion returned None for workout 1
2025-04-29 22:42:52,465 - fit_converter - ERROR - Error converting bike workout to FIT: timestamp encoded value -629950709 is not in valid range [0, 4294967295]
2025-04-29 22:42:52,466 - web - ERROR - FIT conversion returned None for workout 1
2025-04-29 22:43:16,938 - fit_converter - ERROR - Error converting bike workout to FIT: timestamp encoded value -629950709 is not in valid range [0, 4294967295]
2025-04-29 22:43:16,938 - web - ERROR - FIT conversion returned None for workout 1
2025-04-29 22:44:13,876 - fit_converter - ERROR - Error converting bike workout to FIT: timestamp encoded value -629950709 is not in valid range [0, 4294967295]
2025-04-29 22:44:13,877 - web - ERROR - FIT conversion returned None for workout 1
2025-04-29 22:53:38,434 - fit_converter - ERROR - Error creating FileIdMessage: time_created encoded value -629950684 is not in valid range [0, 4294967295]
2025-04-29 22:53:38,435 - fit_converter - ERROR - Failed to create FileIdMessage
2025-04-29 22:53:38,435 - web - ERROR - FIT conversion returned None for workout 1
2025-04-29 22:55:49,749 - fit_converter - ERROR - Error creating FileIdMessage: time_created encoded value -629950684 is not in valid range [0, 4294967295]
2025-04-29 22:55:49,750 - fit_converter - ERROR - Failed to create FileIdMessage
2025-04-29 22:55:49,750 - web - ERROR - FIT conversion returned None for workout 1
2025-04-29 22:56:01,607 - fit_converter - ERROR - Error creating FileIdMessage: time_created encoded value -629950684 is not in valid range [0, 4294967295]
2025-04-29 22:56:01,607 - fit_converter - ERROR - Failed to create FileIdMessage
2025-04-29 22:56:01,608 - web - ERROR - FIT conversion returned None for workout 1
2025-04-29 22:57:57,727 - fit_converter - ERROR - Error creating FileIdMessage: time_created encoded value -629950684 is not in valid range [0, 4294967295]
2025-04-29 22:57:57,728 - test_fit - ERROR - FileIdMessage creation failed! The fix did not work.
2025-04-30 06:15:34,040 - fit_converter - ERROR - Error creating FileIdMessage: time_created encoded value -630065600 is not in valid range [0, 4294967295]
2025-04-30 06:15:34,040 - test_fit - ERROR - FileIdMessage creation failed! The fix did not work.
2025-04-30 06:16:41,512 - fit_converter - ERROR - Error creating FileIdMessage: 'FitFileBuilder' object has no attribute 'messages'
2025-04-30 06:16:41,512 - test_fit - ERROR - FileIdMessage creation failed! The fix did not work.
2025-04-30 06:16:59,097 - fit_converter - ERROR - Error creating FileIdMessage: 'FitFileBuilder' object has no attribute 'messages'
2025-04-30 06:16:59,098 - test_fit - ERROR - FileIdMessage creation failed! The fix did not work.
2025-04-30 06:17:26,504 - fit_converter - ERROR - Error converting bike workout to FIT: timestamp encoded value -629950657 is not in valid range [0, 4294967295]
2025-04-30 06:17:26,505 - test_fit - ERROR - Failed to create FIT file
2025-04-30 06:17:26,505 - test_fit - ERROR - Full FIT conversion failed! The fix did not solve all problems.
2025-04-30 06:34:45,246 - fit_converter - ERROR - Error converting bike workout to FIT: timestamp encoded value -629950656 is not in valid range [0, 4294967295]
2025-04-30 06:34:45,248 - test_fit - ERROR - Failed to create FIT file
2025-04-30 06:34:45,248 - test_fit - ERROR - Full FIT conversion failed! The fix did not solve all problems.
2025-04-30 06:35:01,220 - web - ERROR - Error getting workouts: 'str' object cannot be interpreted as an integer
Traceback (most recent call last):
  File "C:\Users\dougl\rogue_garmin_bridge\src\web\app.py", line 367, in get_workouts
    workouts = workout_manager.get_workouts(limit, offset)
               ^^^^^^^^^^^^^^^^^^^^^^^^^^^^^^^^^^^^^^^^^^^
  File "C:\Users\dougl\rogue_garmin_bridge\src\data\workout_manager.py", line 325, in get_workouts
    return self.database.get_workouts(limit, offset)
           ^^^^^^^^^^^^^^^^^^^^^^^^^^^^^^^^^^^^^^^^^
  File "C:\Users\dougl\rogue_garmin_bridge\src\data\database.py", line 515, in get_workouts
    workout['start_time_iso'] = datetime.fromtimestamp(
                                ^^^^^^^^^^^^^^^^^^^^^^^
TypeError: 'str' object cannot be interpreted as an integer
2025-04-30 06:35:07,224 - web - ERROR - Error getting workouts: 'str' object cannot be interpreted as an integer
Traceback (most recent call last):
  File "C:\Users\dougl\rogue_garmin_bridge\src\web\app.py", line 367, in get_workouts
    workouts = workout_manager.get_workouts(limit, offset)
               ^^^^^^^^^^^^^^^^^^^^^^^^^^^^^^^^^^^^^^^^^^^
  File "C:\Users\dougl\rogue_garmin_bridge\src\data\workout_manager.py", line 325, in get_workouts
    return self.database.get_workouts(limit, offset)
           ^^^^^^^^^^^^^^^^^^^^^^^^^^^^^^^^^^^^^^^^^
  File "C:\Users\dougl\rogue_garmin_bridge\src\data\database.py", line 515, in get_workouts
    workout['start_time_iso'] = datetime.fromtimestamp(
                                ^^^^^^^^^^^^^^^^^^^^^^^
TypeError: 'str' object cannot be interpreted as an integer
2025-04-30 07:02:35,980 - database - ERROR - Error getting workouts: no such column: type
2025-04-30 07:02:46,372 - database - ERROR - Error getting workouts: no such column: type
2025-04-30 07:05:00,716 - web - ERROR - Error getting workouts: 'str' object cannot be interpreted as an integer
Traceback (most recent call last):
  File "C:\Users\dougl\rogue_garmin_bridge\src\web\app.py", line 367, in get_workouts
    workouts = workout_manager.get_workouts(limit, offset)
               ^^^^^^^^^^^^^^^^^^^^^^^^^^^^^^^^^^^^^^^^^^^
  File "C:\Users\dougl\rogue_garmin_bridge\src\data\workout_manager.py", line 325, in get_workouts
    return self.database.get_workouts(limit, offset)
           ^^^^^^^^^^^^^^^^^^^^^^^^^^^^^^^^^^^^^^^^^
  File "C:\Users\dougl\rogue_garmin_bridge\src\data\database.py", line 508, in get_workouts
    workout['start_time_iso'] = datetime.fromtimestamp(
                                ^^^^^^^^^^^^^^^^^^^^^^^
TypeError: 'str' object cannot be interpreted as an integer
2025-04-30 07:08:45,418 - fit_converter - ERROR - Error converting bike workout to FIT: timestamp encoded value -629950654 is not in valid range [0, 4294967295]
2025-04-30 07:08:45,418 - test_fit - ERROR - Failed to create FIT file
2025-04-30 07:08:45,418 - test_fit - ERROR - Full FIT conversion failed! The fix did not solve all problems.
2025-04-30 07:09:00,256 - fit_converter - ERROR - Error converting bike workout to FIT: timestamp encoded value -629950654 is not in valid range [0, 4294967295]
2025-04-30 07:09:00,257 - test_fit - ERROR - Failed to create FIT file
2025-04-30 07:09:00,257 - test_fit - ERROR - Full FIT conversion failed! The fix did not solve all problems.
2025-04-30 07:09:15,812 - fit_converter - ERROR - Error converting bike workout to FIT: timestamp encoded value -629950691 is not in valid range [0, 4294967295]
2025-04-30 07:09:15,812 - web - ERROR - FIT conversion returned None for workout 1
2025-04-30 16:48:17,710 - fit_converter - ERROR - Error converting bike workout to FIT: timestamp encoded value -629950691 is not in valid range [0, 4294967295]
2025-04-30 16:48:17,712 - web - ERROR - FIT conversion returned None for workout 1
2025-04-30 19:44:28,028 - fit_converter - ERROR - Error converting bike workout to FIT: timestamp encoded value -629950691 is not in valid range [0, 4294967295]
2025-04-30 19:44:28,029 - web - ERROR - FIT conversion returned None for workout 1
2025-04-30 20:06:11,914 - fit_converter - ERROR - Error converting bike workout to FIT: timestamp encoded value -629950691 is not in valid range [0, 4294967295]
2025-04-30 20:06:11,914 - web - ERROR - FIT conversion returned None for workout 1
2025-04-30 20:35:43,002 - fit_converter - ERROR - Error converting bike workout to FIT: timestamp encoded value -629950691 is not in valid range [0, 4294967295]
2025-04-30 20:35:43,002 - web - ERROR - FIT conversion returned None for workout 1
2025-04-30 20:45:54,245 - fit_converter - ERROR - Error converting bike workout to FIT: timestamp encoded value -629950691 is not in valid range [0, 4294967295]
2025-04-30 20:45:54,245 - web - ERROR - FIT conversion returned None for workout 1
2025-04-30 20:46:14,881 - fit_converter - ERROR - Error converting bike workout to FIT: timestamp encoded value -629950691 is not in valid range [0, 4294967295]
2025-04-30 20:46:14,882 - web - ERROR - FIT conversion returned None for workout 1
2025-04-30 20:46:38,270 - fit_converter - ERROR - Error converting bike workout to FIT: timestamp encoded value -629950691 is not in valid range [0, 4294967295]
2025-04-30 20:46:38,270 - web - ERROR - FIT conversion returned None for workout 1
2025-04-30 20:49:25,422 - fit_converter - ERROR - Error converting bike workout to FIT: timestamp encoded value -629950691 is not in valid range [0, 4294967295]
2025-04-30 20:49:25,423 - web - ERROR - FIT conversion returned None for workout 1
2025-04-30 20:49:40,927 - fit_converter - ERROR - Error converting bike workout to FIT: timestamp encoded value -629950691 is not in valid range [0, 4294967295]
2025-04-30 20:49:40,927 - web - ERROR - FIT conversion returned None for workout 1
2025-04-30 20:51:49,641 - fit_converter - ERROR - Error converting bike workout to FIT: timestamp encoded value -629950691 is not in valid range [0, 4294967295]
2025-04-30 20:51:49,642 - web - ERROR - FIT conversion returned None for workout 1
2025-04-30 20:52:05,180 - fit_converter - ERROR - Error converting bike workout to FIT: timestamp encoded value -629950691 is not in valid range [0, 4294967295]
2025-04-30 20:52:05,181 - web - ERROR - FIT conversion returned None for workout 1
2025-04-30 20:54:16,263 - fit_converter - ERROR - Error converting bike workout to FIT: timestamp encoded value -629950691 is not in valid range [0, 4294967295]
2025-04-30 20:54:16,264 - web - ERROR - FIT conversion returned None for workout 1
2025-04-30 20:55:21,861 - fit_converter - ERROR - Error converting bike workout to FIT: timestamp encoded value -629950690 is not in valid range [0, 4294967295]
2025-04-30 20:55:21,862 - web - ERROR - FIT conversion returned None for workout 3
2025-04-30 20:58:18,038 - fit_converter - ERROR - Error converting bike workout to FIT: timestamp encoded value -629950690 is not in valid range [0, 4294967295]
2025-04-30 20:58:18,039 - web - ERROR - FIT conversion returned None for workout 3
2025-04-30 20:59:12,742 - fit_converter - ERROR - Error converting bike workout to FIT: timestamp encoded value -629950690 is not in valid range [0, 4294967295]
2025-04-30 20:59:12,742 - web - ERROR - FIT conversion returned None for workout 3
2025-04-30 20:59:36,273 - fit_converter - ERROR - Error converting bike workout to FIT: timestamp encoded value -629950690 is not in valid range [0, 4294967295]
2025-04-30 20:59:36,273 - web - ERROR - FIT conversion returned None for workout 3
2025-04-30 21:03:17,079 - fit_converter - ERROR - Error converting bike workout to FIT: timestamp encoded value -629950690 is not in valid range [0, 4294967295]
2025-04-30 21:03:17,080 - web - ERROR - FIT conversion returned None for workout 3
2025-04-30 21:05:44,723 - fit_converter - ERROR - Error converting bike workout to FIT: timestamp encoded value -629950690 is not in valid range [0, 4294967295]
2025-04-30 21:05:44,724 - web - ERROR - FIT conversion returned None for workout 3
2025-04-30 21:05:57,353 - fit_converter - ERROR - Error converting bike workout to FIT: timestamp encoded value -629950690 is not in valid range [0, 4294967295]
2025-04-30 21:05:57,354 - web - ERROR - FIT conversion returned None for workout 4
2025-04-30 21:16:51,944 - fit_converter - ERROR - Error creating FileIdMessage: time_created encoded value -629950603 is not in valid range [0, 4294967295]
2025-04-30 21:16:51,945 - fit_converter - ERROR - Failed to create FileIdMessage
2025-04-30 21:16:51,945 - web - ERROR - FIT conversion returned None for workout 4
2025-04-30 21:22:05,374 - fit_converter - ERROR - Error creating FileIdMessage: time_created encoded value -629950603 is not in valid range [0, 4294967295]
2025-04-30 21:22:05,374 - fit_converter - ERROR - Failed to create FileIdMessage
2025-04-30 21:22:05,375 - web - ERROR - FIT conversion returned None for workout 4
2025-04-30 21:23:07,661 - fit_converter - ERROR - Error creating FileIdMessage: time_created encoded value -629950603 is not in valid range [0, 4294967295]
2025-04-30 21:23:07,661 - fit_converter - ERROR - Failed to create FileIdMessage
2025-04-30 21:23:07,662 - web - ERROR - FIT conversion returned None for workout 4
2025-04-30 21:25:49,292 - fit_converter - ERROR - Error creating FileIdMessage: time_created encoded value -629950690 is not in valid range [0, 4294967295]
2025-04-30 21:25:49,293 - fit_converter - ERROR - Failed to create FileIdMessage
2025-04-30 21:25:49,293 - web - ERROR - FIT conversion returned None for workout 4
2025-04-30 21:26:09,146 - fit_converter - ERROR - Error creating FileIdMessage: time_created encoded value -629950691 is not in valid range [0, 4294967295]
2025-04-30 21:26:09,146 - fit_converter - ERROR - Failed to create FileIdMessage
2025-04-30 21:26:09,147 - web - ERROR - FIT conversion returned None for workout 1
2025-04-30 21:30:22,115 - fit_converter - ERROR - Error creating FileIdMessage: time_created encoded value -629950691 is not in valid range [0, 4294967295]
2025-04-30 21:30:22,115 - fit_converter - ERROR - Failed to create FileIdMessage
2025-04-30 21:30:22,115 - web - ERROR - FIT conversion returned None for workout 1
2025-04-30 21:36:01,823 - fit_converter - ERROR - Error creating FileIdMessage: time_created encoded value -629950691 is not in valid range [0, 4294967295]
2025-04-30 21:36:01,824 - fit_converter - ERROR - Failed to create FileIdMessage
2025-04-30 21:36:01,824 - web - ERROR - FIT conversion returned None for workout 1
2025-04-30 21:36:20,555 - fit_converter - ERROR - Error creating FileIdMessage: time_created encoded value -629950690 is not in valid range [0, 4294967295]
2025-04-30 21:36:20,555 - fit_converter - ERROR - Failed to create FileIdMessage
2025-04-30 21:36:20,555 - web - ERROR - FIT conversion returned None for workout 3
2025-04-30 21:38:07,515 - fit_converter - ERROR - Error creating FileIdMessage: time_created encoded value -629950690 is not in valid range [0, 4294967295]
2025-04-30 21:38:07,515 - fit_converter - ERROR - Failed to create FileIdMessage
2025-04-30 21:38:07,515 - web - ERROR - FIT conversion returned None for workout 3
2025-04-30 21:46:44,418 - fit_converter - ERROR - Error creating FileIdMessage: time_created encoded value -629950690 is not in valid range [0, 4294967295]
2025-04-30 21:46:44,419 - fit_converter - ERROR - Failed to create FileIdMessage
2025-04-30 21:46:44,419 - web - ERROR - FIT conversion returned None for workout 3
2025-04-30 21:46:58,619 - fit_converter - ERROR - Error creating FileIdMessage: time_created encoded value -629950690 is not in valid range [0, 4294967295]
2025-04-30 21:46:58,619 - fit_converter - ERROR - Failed to create FileIdMessage
2025-04-30 21:46:58,620 - web - ERROR - FIT conversion returned None for workout 3
2025-04-30 21:50:20,449 - fit_converter - ERROR - Error creating FileIdMessage: time_created encoded value -629950601 is not in valid range [0, 4294967295]
2025-04-30 21:50:20,449 - fit_converter - ERROR - Failed to create FileIdMessage
2025-04-30 21:50:20,449 - web - ERROR - FIT conversion returned None for workout 3
2025-04-30 21:51:23,422 - fit_converter - ERROR - Error converting bike workout to FIT: timestamp encoded value -629950690 is not in valid range [0, 4294967295]
2025-04-30 21:51:23,422 - web - ERROR - FIT conversion returned None for workout 3
2025-05-01 06:18:22,807 - fit_converter - ERROR - Error converting bike workout to FIT: timestamp encoded value -629950691 is not in valid range [0, 4294967295]
2025-05-01 06:18:22,808 - web - ERROR - FIT conversion returned None for workout 1
2025-05-01 06:35:04,780 - workout_manager - ERROR - Error deleting workout: 'Database' object has no attribute '_connect'
Traceback (most recent call last):
  File "C:\Users\dougl\rogue_garmin_bridge\src\data\workout_manager.py", line 724, in delete_workout
    self.database._connect()
    ^^^^^^^^^^^^^^^^^^^^^^
AttributeError: 'Database' object has no attribute '_connect'
2025-05-01 06:35:11,472 - workout_manager - ERROR - Error deleting workout: 'Database' object has no attribute '_connect'
Traceback (most recent call last):
  File "C:\Users\dougl\rogue_garmin_bridge\src\data\workout_manager.py", line 724, in delete_workout
    self.database._connect()
    ^^^^^^^^^^^^^^^^^^^^^^
AttributeError: 'Database' object has no attribute '_connect'
2025-05-01 19:53:17,542 - web - ERROR - Error getting workout summary: 'WorkoutManager' object has no attribute 'get_workout_summary_metrics'
2025-05-01 19:53:18,241 - web - ERROR - Error getting workout summary: 'WorkoutManager' object has no attribute 'get_workout_summary_metrics'
2025-05-01 19:53:19,550 - web - ERROR - Error getting workout summary: 'WorkoutManager' object has no attribute 'get_workout_summary_metrics'
2025-05-01 19:53:20,233 - web - ERROR - Error getting workout summary: 'WorkoutManager' object has no attribute 'get_workout_summary_metrics'
2025-05-01 19:53:21,549 - web - ERROR - Error getting workout summary: 'WorkoutManager' object has no attribute 'get_workout_summary_metrics'
2025-05-01 19:53:22,241 - web - ERROR - Error getting workout summary: 'WorkoutManager' object has no attribute 'get_workout_summary_metrics'
2025-05-01 19:53:23,548 - web - ERROR - Error getting workout summary: 'WorkoutManager' object has no attribute 'get_workout_summary_metrics'
2025-05-01 19:53:24,230 - web - ERROR - Error getting workout summary: 'WorkoutManager' object has no attribute 'get_workout_summary_metrics'
2025-05-01 19:53:25,543 - web - ERROR - Error getting workout summary: 'WorkoutManager' object has no attribute 'get_workout_summary_metrics'
2025-05-01 19:53:26,237 - web - ERROR - Error getting workout summary: 'WorkoutManager' object has no attribute 'get_workout_summary_metrics'
2025-05-01 19:53:27,551 - web - ERROR - Error getting workout summary: 'WorkoutManager' object has no attribute 'get_workout_summary_metrics'
2025-05-01 19:53:28,231 - web - ERROR - Error getting workout summary: 'WorkoutManager' object has no attribute 'get_workout_summary_metrics'
2025-05-01 19:53:29,543 - web - ERROR - Error getting workout summary: 'WorkoutManager' object has no attribute 'get_workout_summary_metrics'
2025-05-01 19:53:30,237 - web - ERROR - Error getting workout summary: 'WorkoutManager' object has no attribute 'get_workout_summary_metrics'
2025-05-01 19:53:31,548 - web - ERROR - Error getting workout summary: 'WorkoutManager' object has no attribute 'get_workout_summary_metrics'
2025-05-01 19:53:32,241 - web - ERROR - Error getting workout summary: 'WorkoutManager' object has no attribute 'get_workout_summary_metrics'
2025-05-01 19:53:33,552 - web - ERROR - Error getting workout summary: 'WorkoutManager' object has no attribute 'get_workout_summary_metrics'
2025-05-01 19:53:34,231 - web - ERROR - Error getting workout summary: 'WorkoutManager' object has no attribute 'get_workout_summary_metrics'
2025-05-01 19:53:35,543 - web - ERROR - Error getting workout summary: 'WorkoutManager' object has no attribute 'get_workout_summary_metrics'
2025-05-01 19:53:36,244 - web - ERROR - Error getting workout summary: 'WorkoutManager' object has no attribute 'get_workout_summary_metrics'
2025-05-01 19:53:37,540 - web - ERROR - Error getting workout summary: 'WorkoutManager' object has no attribute 'get_workout_summary_metrics'
2025-05-01 19:53:49,922 - web - ERROR - Error getting workout summary: 'WorkoutManager' object has no attribute 'get_workout_summary_metrics'
2025-05-01 19:53:49,926 - web - ERROR - Error getting workout summary: 'WorkoutManager' object has no attribute 'get_workout_summary_metrics'
2025-05-01 19:53:50,926 - web - ERROR - Error getting workout summary: 'WorkoutManager' object has no attribute 'get_workout_summary_metrics'
2025-05-01 19:53:51,622 - web - ERROR - Error getting workout summary: 'WorkoutManager' object has no attribute 'get_workout_summary_metrics'
2025-05-01 19:53:52,937 - web - ERROR - Error getting workout summary: 'WorkoutManager' object has no attribute 'get_workout_summary_metrics'
2025-05-01 19:53:53,615 - web - ERROR - Error getting workout summary: 'WorkoutManager' object has no attribute 'get_workout_summary_metrics'
2025-05-01 19:53:54,929 - web - ERROR - Error getting workout summary: 'WorkoutManager' object has no attribute 'get_workout_summary_metrics'
2025-05-01 19:54:15,018 - web - ERROR - Error getting workout summary: 'WorkoutManager' object has no attribute 'get_workout_summary_metrics'
2025-05-01 19:54:15,026 - web - ERROR - Error getting workout summary: 'WorkoutManager' object has no attribute 'get_workout_summary_metrics'
2025-05-01 19:54:16,026 - web - ERROR - Error getting workout summary: 'WorkoutManager' object has no attribute 'get_workout_summary_metrics'
2025-05-01 19:54:16,720 - web - ERROR - Error getting workout summary: 'WorkoutManager' object has no attribute 'get_workout_summary_metrics'
2025-05-01 19:54:18,034 - web - ERROR - Error getting workout summary: 'WorkoutManager' object has no attribute 'get_workout_summary_metrics'
2025-05-01 19:54:18,712 - web - ERROR - Error getting workout summary: 'WorkoutManager' object has no attribute 'get_workout_summary_metrics'
2025-05-01 19:54:20,033 - web - ERROR - Error getting workout summary: 'WorkoutManager' object has no attribute 'get_workout_summary_metrics'
2025-05-01 19:54:20,756 - web - ERROR - Error getting workout summary: 'WorkoutManager' object has no attribute 'get_workout_summary_metrics'
2025-05-01 19:54:22,041 - web - ERROR - Error getting workout summary: 'WorkoutManager' object has no attribute 'get_workout_summary_metrics'
2025-05-01 19:54:22,723 - web - ERROR - Error getting workout summary: 'WorkoutManager' object has no attribute 'get_workout_summary_metrics'
2025-05-01 19:54:24,037 - web - ERROR - Error getting workout summary: 'WorkoutManager' object has no attribute 'get_workout_summary_metrics'
2025-05-01 19:54:24,718 - web - ERROR - Error getting workout summary: 'WorkoutManager' object has no attribute 'get_workout_summary_metrics'
2025-05-01 19:54:26,037 - web - ERROR - Error getting workout summary: 'WorkoutManager' object has no attribute 'get_workout_summary_metrics'
2025-05-01 19:54:26,729 - web - ERROR - Error getting workout summary: 'WorkoutManager' object has no attribute 'get_workout_summary_metrics'
2025-05-01 19:54:28,027 - web - ERROR - Error getting workout summary: 'WorkoutManager' object has no attribute 'get_workout_summary_metrics'
2025-05-01 19:54:28,724 - web - ERROR - Error getting workout summary: 'WorkoutManager' object has no attribute 'get_workout_summary_metrics'
2025-05-01 19:54:30,031 - web - ERROR - Error getting workout summary: 'WorkoutManager' object has no attribute 'get_workout_summary_metrics'
2025-05-01 19:54:30,716 - web - ERROR - Error getting workout summary: 'WorkoutManager' object has no attribute 'get_workout_summary_metrics'
2025-05-01 19:54:32,035 - web - ERROR - Error getting workout summary: 'WorkoutManager' object has no attribute 'get_workout_summary_metrics'
2025-05-01 19:54:32,727 - web - ERROR - Error getting workout summary: 'WorkoutManager' object has no attribute 'get_workout_summary_metrics'
2025-05-01 19:54:34,038 - web - ERROR - Error getting workout summary: 'WorkoutManager' object has no attribute 'get_workout_summary_metrics'
2025-05-01 19:54:34,719 - web - ERROR - Error getting workout summary: 'WorkoutManager' object has no attribute 'get_workout_summary_metrics'
2025-05-01 19:54:36,036 - web - ERROR - Error getting workout summary: 'WorkoutManager' object has no attribute 'get_workout_summary_metrics'
2025-05-01 19:54:36,726 - web - ERROR - Error getting workout summary: 'WorkoutManager' object has no attribute 'get_workout_summary_metrics'
2025-05-01 19:54:38,024 - web - ERROR - Error getting workout summary: 'WorkoutManager' object has no attribute 'get_workout_summary_metrics'
2025-05-01 19:54:38,722 - web - ERROR - Error getting workout summary: 'WorkoutManager' object has no attribute 'get_workout_summary_metrics'
2025-05-01 19:54:40,033 - web - ERROR - Error getting workout summary: 'WorkoutManager' object has no attribute 'get_workout_summary_metrics'
2025-05-01 19:54:40,722 - web - ERROR - Error getting workout summary: 'WorkoutManager' object has no attribute 'get_workout_summary_metrics'
2025-05-01 19:54:42,025 - web - ERROR - Error getting workout summary: 'WorkoutManager' object has no attribute 'get_workout_summary_metrics'
2025-05-01 19:54:42,720 - web - ERROR - Error getting workout summary: 'WorkoutManager' object has no attribute 'get_workout_summary_metrics'
2025-05-01 19:54:44,037 - web - ERROR - Error getting workout summary: 'WorkoutManager' object has no attribute 'get_workout_summary_metrics'
2025-05-01 19:54:44,724 - web - ERROR - Error getting workout summary: 'WorkoutManager' object has no attribute 'get_workout_summary_metrics'
2025-05-01 19:54:46,025 - web - ERROR - Error getting workout summary: 'WorkoutManager' object has no attribute 'get_workout_summary_metrics'
2025-05-01 19:54:46,720 - web - ERROR - Error getting workout summary: 'WorkoutManager' object has no attribute 'get_workout_summary_metrics'
2025-05-01 19:54:48,028 - web - ERROR - Error getting workout summary: 'WorkoutManager' object has no attribute 'get_workout_summary_metrics'
2025-05-01 19:54:48,722 - web - ERROR - Error getting workout summary: 'WorkoutManager' object has no attribute 'get_workout_summary_metrics'
2025-05-01 19:54:50,036 - web - ERROR - Error getting workout summary: 'WorkoutManager' object has no attribute 'get_workout_summary_metrics'
2025-05-01 19:54:50,719 - web - ERROR - Error getting workout summary: 'WorkoutManager' object has no attribute 'get_workout_summary_metrics'
2025-05-01 19:54:52,041 - web - ERROR - Error getting workout summary: 'WorkoutManager' object has no attribute 'get_workout_summary_metrics'
2025-05-01 19:54:52,719 - web - ERROR - Error getting workout summary: 'WorkoutManager' object has no attribute 'get_workout_summary_metrics'
2025-05-01 19:54:54,033 - web - ERROR - Error getting workout summary: 'WorkoutManager' object has no attribute 'get_workout_summary_metrics'
2025-05-01 19:54:54,716 - web - ERROR - Error getting workout summary: 'WorkoutManager' object has no attribute 'get_workout_summary_metrics'
2025-05-01 19:54:56,038 - web - ERROR - Error getting workout summary: 'WorkoutManager' object has no attribute 'get_workout_summary_metrics'
2025-05-01 19:54:56,716 - web - ERROR - Error getting workout summary: 'WorkoutManager' object has no attribute 'get_workout_summary_metrics'
2025-05-01 19:54:58,027 - web - ERROR - Error getting workout summary: 'WorkoutManager' object has no attribute 'get_workout_summary_metrics'
2025-05-01 19:54:58,290 - web - ERROR - Error ending workout: WorkoutManager.end_workout() takes 1 positional argument but 2 were given
2025-05-01 19:55:03,115 - web - ERROR - Error getting workout summary: 'WorkoutManager' object has no attribute 'get_workout_summary_metrics'
2025-05-01 19:55:04,023 - web - ERROR - Error getting workout summary: 'WorkoutManager' object has no attribute 'get_workout_summary_metrics'
2025-05-01 19:55:04,719 - web - ERROR - Error getting workout summary: 'WorkoutManager' object has no attribute 'get_workout_summary_metrics'
2025-05-01 19:55:05,057 - web - ERROR - Error ending workout: WorkoutManager.end_workout() takes 1 positional argument but 2 were given
2025-05-01 19:58:11,962 - web - ERROR - Error getting workout summary: 'WorkoutManager' object has no attribute 'get_workout_summary_metrics'
2025-05-01 19:58:11,968 - web - ERROR - Error getting workout summary: 'WorkoutManager' object has no attribute 'get_workout_summary_metrics'
2025-05-01 19:58:12,977 - web - ERROR - Error getting workout summary: 'WorkoutManager' object has no attribute 'get_workout_summary_metrics'
2025-05-01 19:58:13,663 - web - ERROR - Error getting workout summary: 'WorkoutManager' object has no attribute 'get_workout_summary_metrics'
2025-05-01 19:58:14,977 - web - ERROR - Error getting workout summary: 'WorkoutManager' object has no attribute 'get_workout_summary_metrics'
2025-05-01 19:58:15,673 - web - ERROR - Error getting workout summary: 'WorkoutManager' object has no attribute 'get_workout_summary_metrics'
2025-05-01 19:58:16,987 - web - ERROR - Error getting workout summary: 'WorkoutManager' object has no attribute 'get_workout_summary_metrics'
2025-05-01 19:58:17,664 - web - ERROR - Error getting workout summary: 'WorkoutManager' object has no attribute 'get_workout_summary_metrics'
2025-05-01 19:58:18,973 - web - ERROR - Error getting workout summary: 'WorkoutManager' object has no attribute 'get_workout_summary_metrics'
2025-05-01 19:58:19,666 - web - ERROR - Error getting workout summary: 'WorkoutManager' object has no attribute 'get_workout_summary_metrics'
2025-05-01 19:58:20,984 - web - ERROR - Error getting workout summary: 'WorkoutManager' object has no attribute 'get_workout_summary_metrics'
2025-05-01 19:58:21,665 - web - ERROR - Error getting workout summary: 'WorkoutManager' object has no attribute 'get_workout_summary_metrics'
2025-05-01 19:58:22,983 - web - ERROR - Error getting workout summary: 'WorkoutManager' object has no attribute 'get_workout_summary_metrics'
2025-05-01 19:58:23,665 - web - ERROR - Error getting workout summary: 'WorkoutManager' object has no attribute 'get_workout_summary_metrics'
2025-05-01 19:58:24,972 - web - ERROR - Error getting workout summary: 'WorkoutManager' object has no attribute 'get_workout_summary_metrics'
2025-05-01 19:58:25,665 - web - ERROR - Error getting workout summary: 'WorkoutManager' object has no attribute 'get_workout_summary_metrics'
2025-05-01 19:58:26,988 - web - ERROR - Error getting workout summary: 'WorkoutManager' object has no attribute 'get_workout_summary_metrics'
2025-05-01 19:58:27,671 - web - ERROR - Error getting workout summary: 'WorkoutManager' object has no attribute 'get_workout_summary_metrics'
2025-05-01 19:58:28,972 - web - ERROR - Error getting workout summary: 'WorkoutManager' object has no attribute 'get_workout_summary_metrics'
2025-05-01 19:58:29,665 - web - ERROR - Error getting workout summary: 'WorkoutManager' object has no attribute 'get_workout_summary_metrics'
2025-05-01 19:58:30,985 - web - ERROR - Error getting workout summary: 'WorkoutManager' object has no attribute 'get_workout_summary_metrics'
2025-05-01 19:58:31,664 - web - ERROR - Error getting workout summary: 'WorkoutManager' object has no attribute 'get_workout_summary_metrics'
2025-05-01 19:58:32,980 - web - ERROR - Error getting workout summary: 'WorkoutManager' object has no attribute 'get_workout_summary_metrics'
2025-05-01 19:58:33,665 - web - ERROR - Error getting workout summary: 'WorkoutManager' object has no attribute 'get_workout_summary_metrics'
2025-05-01 19:58:34,973 - web - ERROR - Error getting workout summary: 'WorkoutManager' object has no attribute 'get_workout_summary_metrics'
2025-05-01 19:58:35,669 - web - ERROR - Error getting workout summary: 'WorkoutManager' object has no attribute 'get_workout_summary_metrics'
2025-05-01 19:58:36,972 - web - ERROR - Error getting workout summary: 'WorkoutManager' object has no attribute 'get_workout_summary_metrics'
2025-05-01 19:58:37,666 - web - ERROR - Error getting workout summary: 'WorkoutManager' object has no attribute 'get_workout_summary_metrics'
2025-05-01 19:58:38,979 - web - ERROR - Error getting workout summary: 'WorkoutManager' object has no attribute 'get_workout_summary_metrics'
2025-05-01 19:58:39,676 - web - ERROR - Error getting workout summary: 'WorkoutManager' object has no attribute 'get_workout_summary_metrics'
2025-05-01 19:58:40,985 - web - ERROR - Error getting workout summary: 'WorkoutManager' object has no attribute 'get_workout_summary_metrics'
2025-05-01 19:58:41,673 - web - ERROR - Error getting workout summary: 'WorkoutManager' object has no attribute 'get_workout_summary_metrics'
2025-05-01 19:58:42,988 - web - ERROR - Error getting workout summary: 'WorkoutManager' object has no attribute 'get_workout_summary_metrics'
2025-05-01 19:58:43,680 - web - ERROR - Error getting workout summary: 'WorkoutManager' object has no attribute 'get_workout_summary_metrics'
2025-05-01 19:58:44,972 - web - ERROR - Error getting workout summary: 'WorkoutManager' object has no attribute 'get_workout_summary_metrics'
2025-05-01 19:58:45,662 - web - ERROR - Error getting workout summary: 'WorkoutManager' object has no attribute 'get_workout_summary_metrics'
2025-05-01 19:58:46,980 - web - ERROR - Error getting workout summary: 'WorkoutManager' object has no attribute 'get_workout_summary_metrics'
2025-05-01 19:58:47,672 - web - ERROR - Error getting workout summary: 'WorkoutManager' object has no attribute 'get_workout_summary_metrics'
2025-05-01 19:58:48,974 - web - ERROR - Error getting workout summary: 'WorkoutManager' object has no attribute 'get_workout_summary_metrics'
2025-05-01 19:58:49,668 - web - ERROR - Error getting workout summary: 'WorkoutManager' object has no attribute 'get_workout_summary_metrics'
2025-05-01 19:58:50,980 - web - ERROR - Error getting workout summary: 'WorkoutManager' object has no attribute 'get_workout_summary_metrics'
2025-05-01 19:58:51,664 - web - ERROR - Error getting workout summary: 'WorkoutManager' object has no attribute 'get_workout_summary_metrics'
2025-05-01 19:58:52,980 - web - ERROR - Error getting workout summary: 'WorkoutManager' object has no attribute 'get_workout_summary_metrics'
2025-05-01 19:58:53,673 - web - ERROR - Error getting workout summary: 'WorkoutManager' object has no attribute 'get_workout_summary_metrics'
2025-05-01 19:58:54,979 - web - ERROR - Error getting workout summary: 'WorkoutManager' object has no attribute 'get_workout_summary_metrics'
2025-05-01 19:58:55,667 - web - ERROR - Error getting workout summary: 'WorkoutManager' object has no attribute 'get_workout_summary_metrics'
2025-05-01 19:58:56,981 - web - ERROR - Error getting workout summary: 'WorkoutManager' object has no attribute 'get_workout_summary_metrics'
2025-05-01 19:58:57,677 - web - ERROR - Error getting workout summary: 'WorkoutManager' object has no attribute 'get_workout_summary_metrics'
2025-05-01 19:58:58,975 - web - ERROR - Error getting workout summary: 'WorkoutManager' object has no attribute 'get_workout_summary_metrics'
2025-05-01 19:58:59,672 - web - ERROR - Error getting workout summary: 'WorkoutManager' object has no attribute 'get_workout_summary_metrics'
2025-05-01 19:59:00,971 - web - ERROR - Error getting workout summary: 'WorkoutManager' object has no attribute 'get_workout_summary_metrics'
2025-05-01 19:59:01,672 - web - ERROR - Error getting workout summary: 'WorkoutManager' object has no attribute 'get_workout_summary_metrics'
2025-05-01 19:59:02,975 - web - ERROR - Error getting workout summary: 'WorkoutManager' object has no attribute 'get_workout_summary_metrics'
2025-05-01 19:59:03,668 - web - ERROR - Error getting workout summary: 'WorkoutManager' object has no attribute 'get_workout_summary_metrics'
2025-05-01 19:59:04,968 - web - ERROR - Error getting workout summary: 'WorkoutManager' object has no attribute 'get_workout_summary_metrics'
2025-05-01 19:59:05,670 - web - ERROR - Error getting workout summary: 'WorkoutManager' object has no attribute 'get_workout_summary_metrics'
2025-05-01 19:59:06,976 - web - ERROR - Error getting workout summary: 'WorkoutManager' object has no attribute 'get_workout_summary_metrics'
2025-05-01 19:59:07,665 - web - ERROR - Error getting workout summary: 'WorkoutManager' object has no attribute 'get_workout_summary_metrics'
2025-05-01 19:59:08,965 - web - ERROR - Error getting workout summary: 'WorkoutManager' object has no attribute 'get_workout_summary_metrics'
2025-05-01 19:59:09,224 - fit_converter - ERROR - Error converting bike workout to FIT: time_created encoded value -629319456 is not in valid range [0, 4294967295]
2025-05-03 10:33:37,201 - web - ERROR - FIT conversion returned None for workout 1
2025-05-03 10:49:51,777 - web - ERROR - FIT conversion returned None for workout 1
2025-05-03 11:09:50,299 - web - ERROR - FIT conversion returned None for workout 1
2025-05-03 11:42:20,607 - ftms - ERROR - Connection attempt to C9:02:CB:68:17:C1 timed out after 30 seconds
2025-05-03 11:42:54,188 - web - ERROR - Error getting workout summary: 'WorkoutManager' object has no attribute 'get_workout_summary_metrics'
2025-05-03 11:42:54,193 - web - ERROR - Error getting workout summary: 'WorkoutManager' object has no attribute 'get_workout_summary_metrics'
2025-05-03 11:42:55,190 - web - ERROR - Error getting workout summary: 'WorkoutManager' object has no attribute 'get_workout_summary_metrics'
2025-05-03 11:42:55,881 - web - ERROR - Error getting workout summary: 'WorkoutManager' object has no attribute 'get_workout_summary_metrics'
2025-05-03 11:42:57,197 - web - ERROR - Error getting workout summary: 'WorkoutManager' object has no attribute 'get_workout_summary_metrics'
2025-05-03 11:42:57,878 - web - ERROR - Error getting workout summary: 'WorkoutManager' object has no attribute 'get_workout_summary_metrics'
2025-05-03 11:42:59,193 - web - ERROR - Error getting workout summary: 'WorkoutManager' object has no attribute 'get_workout_summary_metrics'
2025-05-03 11:42:59,892 - web - ERROR - Error getting workout summary: 'WorkoutManager' object has no attribute 'get_workout_summary_metrics'
2025-05-03 11:43:01,195 - web - ERROR - Error getting workout summary: 'WorkoutManager' object has no attribute 'get_workout_summary_metrics'
2025-05-03 11:43:01,888 - web - ERROR - Error getting workout summary: 'WorkoutManager' object has no attribute 'get_workout_summary_metrics'
2025-05-03 11:43:03,201 - web - ERROR - Error getting workout summary: 'WorkoutManager' object has no attribute 'get_workout_summary_metrics'
2025-05-03 11:43:03,884 - web - ERROR - Error getting workout summary: 'WorkoutManager' object has no attribute 'get_workout_summary_metrics'
2025-05-03 11:43:05,198 - web - ERROR - Error getting workout summary: 'WorkoutManager' object has no attribute 'get_workout_summary_metrics'
2025-05-03 11:43:05,885 - web - ERROR - Error getting workout summary: 'WorkoutManager' object has no attribute 'get_workout_summary_metrics'
2025-05-03 11:43:07,196 - web - ERROR - Error getting workout summary: 'WorkoutManager' object has no attribute 'get_workout_summary_metrics'
2025-05-03 11:43:07,882 - web - ERROR - Error getting workout summary: 'WorkoutManager' object has no attribute 'get_workout_summary_metrics'
2025-05-03 11:43:09,197 - web - ERROR - Error getting workout summary: 'WorkoutManager' object has no attribute 'get_workout_summary_metrics'
2025-05-03 11:43:09,890 - web - ERROR - Error getting workout summary: 'WorkoutManager' object has no attribute 'get_workout_summary_metrics'
2025-05-03 11:43:11,189 - web - ERROR - Error getting workout summary: 'WorkoutManager' object has no attribute 'get_workout_summary_metrics'
2025-05-03 11:43:11,881 - web - ERROR - Error getting workout summary: 'WorkoutManager' object has no attribute 'get_workout_summary_metrics'
2025-05-03 11:43:13,192 - web - ERROR - Error getting workout summary: 'WorkoutManager' object has no attribute 'get_workout_summary_metrics'
2025-05-03 11:43:13,882 - web - ERROR - Error getting workout summary: 'WorkoutManager' object has no attribute 'get_workout_summary_metrics'
2025-05-03 11:43:15,194 - web - ERROR - Error getting workout summary: 'WorkoutManager' object has no attribute 'get_workout_summary_metrics'
2025-05-03 11:43:15,879 - web - ERROR - Error getting workout summary: 'WorkoutManager' object has no attribute 'get_workout_summary_metrics'
2025-05-03 11:43:17,191 - web - ERROR - Error getting workout summary: 'WorkoutManager' object has no attribute 'get_workout_summary_metrics'
2025-05-03 11:43:17,878 - web - ERROR - Error getting workout summary: 'WorkoutManager' object has no attribute 'get_workout_summary_metrics'
2025-05-03 11:43:19,199 - web - ERROR - Error getting workout summary: 'WorkoutManager' object has no attribute 'get_workout_summary_metrics'
2025-05-03 11:43:19,878 - web - ERROR - Error getting workout summary: 'WorkoutManager' object has no attribute 'get_workout_summary_metrics'
2025-05-03 11:43:21,192 - web - ERROR - Error getting workout summary: 'WorkoutManager' object has no attribute 'get_workout_summary_metrics'
2025-05-03 11:43:21,886 - web - ERROR - Error getting workout summary: 'WorkoutManager' object has no attribute 'get_workout_summary_metrics'
2025-05-03 11:43:23,201 - web - ERROR - Error getting workout summary: 'WorkoutManager' object has no attribute 'get_workout_summary_metrics'
2025-05-03 11:43:23,879 - web - ERROR - Error getting workout summary: 'WorkoutManager' object has no attribute 'get_workout_summary_metrics'
2025-05-03 11:43:25,188 - web - ERROR - Error getting workout summary: 'WorkoutManager' object has no attribute 'get_workout_summary_metrics'
2025-05-03 11:43:25,883 - web - ERROR - Error getting workout summary: 'WorkoutManager' object has no attribute 'get_workout_summary_metrics'
2025-05-03 11:43:27,192 - web - ERROR - Error getting workout summary: 'WorkoutManager' object has no attribute 'get_workout_summary_metrics'
2025-05-03 11:43:27,887 - web - ERROR - Error getting workout summary: 'WorkoutManager' object has no attribute 'get_workout_summary_metrics'
2025-05-03 11:43:29,194 - web - ERROR - Error getting workout summary: 'WorkoutManager' object has no attribute 'get_workout_summary_metrics'
2025-05-03 11:43:29,884 - web - ERROR - Error getting workout summary: 'WorkoutManager' object has no attribute 'get_workout_summary_metrics'
2025-05-03 11:44:02,085 - web - ERROR - Error getting workout summary: 'WorkoutManager' object has no attribute 'get_workout_summary_metrics'
2025-05-03 11:44:02,091 - web - ERROR - Error getting workout summary: 'WorkoutManager' object has no attribute 'get_workout_summary_metrics'
2025-05-03 11:44:03,087 - web - ERROR - Error getting workout summary: 'WorkoutManager' object has no attribute 'get_workout_summary_metrics'
2025-05-03 11:44:03,781 - web - ERROR - Error getting workout summary: 'WorkoutManager' object has no attribute 'get_workout_summary_metrics'
2025-05-03 11:44:05,084 - web - ERROR - Error getting workout summary: 'WorkoutManager' object has no attribute 'get_workout_summary_metrics'
2025-05-03 11:44:05,779 - web - ERROR - Error getting workout summary: 'WorkoutManager' object has no attribute 'get_workout_summary_metrics'
2025-05-03 11:44:07,100 - web - ERROR - Error getting workout summary: 'WorkoutManager' object has no attribute 'get_workout_summary_metrics'
2025-05-03 11:44:07,772 - web - ERROR - Error getting workout summary: 'WorkoutManager' object has no attribute 'get_workout_summary_metrics'
2025-05-03 11:44:09,086 - web - ERROR - Error getting workout summary: 'WorkoutManager' object has no attribute 'get_workout_summary_metrics'
2025-05-03 11:44:09,783 - web - ERROR - Error getting workout summary: 'WorkoutManager' object has no attribute 'get_workout_summary_metrics'
2025-05-03 11:44:11,085 - web - ERROR - Error getting workout summary: 'WorkoutManager' object has no attribute 'get_workout_summary_metrics'
2025-05-03 11:44:11,775 - web - ERROR - Error getting workout summary: 'WorkoutManager' object has no attribute 'get_workout_summary_metrics'
2025-05-03 11:44:13,085 - web - ERROR - Error getting workout summary: 'WorkoutManager' object has no attribute 'get_workout_summary_metrics'
2025-05-03 11:44:13,339 - fit_converter - ERROR - Error converting bike workout to FIT: time_created encoded value -629319313 is not in valid range [0, 4294967295]
2025-05-03 12:06:23,798 - fit_converter - ERROR - Error converting bike workout to FIT: time_created encoded value -629319312 is not in valid range [0, 4294967295]
2025-05-03 12:06:23,798 - fit_processor - ERROR - Failed to create FIT file for workout 1
2025-05-03 12:13:37,997 - fit_converter - ERROR - Error converting bike workout to FIT: time_created encoded value -629950377 is not in valid range [0, 4294967295]
2025-05-03 12:13:37,998 - fit_processor - ERROR - Failed to create FIT file for workout 1
2025-05-03 12:17:09,710 - fit_converter - ERROR - Error converting bike workout to FIT: time_created encoded value -629319311 is not in valid range [0, 4294967295]
2025-05-03 12:17:09,711 - fit_processor - ERROR - Failed to create FIT file for workout 1
2025-05-03 12:17:24,099 - fit_converter - ERROR - Error converting bike workout to FIT: time_created encoded value -629319311 is not in valid range [0, 4294967295]
2025-05-03 12:17:24,100 - fit_processor - ERROR - Failed to create FIT file for workout 1
2025-05-03 12:21:50,270 - fit_converter - ERROR - Error converting bike workout to FIT: time_created encoded value -629950376 is not in valid range [0, 4294967295]
2025-05-03 12:21:50,271 - fit_processor - ERROR - Failed to create FIT file for workout 1
2025-05-03 12:52:44,920 - web - ERROR - Error getting workout summary: 'WorkoutManager' object has no attribute 'get_workout_summary_metrics'
2025-05-03 12:52:45,309 - web - ERROR - Error getting workout summary: 'WorkoutManager' object has no attribute 'get_workout_summary_metrics'
2025-05-03 12:52:46,008 - web - ERROR - Error getting workout summary: 'WorkoutManager' object has no attribute 'get_workout_summary_metrics'
2025-05-03 12:52:47,318 - web - ERROR - Error getting workout summary: 'WorkoutManager' object has no attribute 'get_workout_summary_metrics'
2025-05-03 12:52:47,999 - web - ERROR - Error getting workout summary: 'WorkoutManager' object has no attribute 'get_workout_summary_metrics'
2025-05-03 12:52:49,311 - web - ERROR - Error getting workout summary: 'WorkoutManager' object has no attribute 'get_workout_summary_metrics'
2025-05-03 12:52:50,012 - web - ERROR - Error getting workout summary: 'WorkoutManager' object has no attribute 'get_workout_summary_metrics'
2025-05-03 12:52:51,308 - web - ERROR - Error getting workout summary: 'WorkoutManager' object has no attribute 'get_workout_summary_metrics'
2025-05-03 12:52:52,002 - web - ERROR - Error getting workout summary: 'WorkoutManager' object has no attribute 'get_workout_summary_metrics'
2025-05-03 12:52:53,319 - web - ERROR - Error getting workout summary: 'WorkoutManager' object has no attribute 'get_workout_summary_metrics'
2025-05-03 12:52:54,000 - web - ERROR - Error getting workout summary: 'WorkoutManager' object has no attribute 'get_workout_summary_metrics'
2025-05-03 12:52:55,326 - web - ERROR - Error getting workout summary: 'WorkoutManager' object has no attribute 'get_workout_summary_metrics'
2025-05-03 12:52:56,005 - web - ERROR - Error getting workout summary: 'WorkoutManager' object has no attribute 'get_workout_summary_metrics'
2025-05-03 12:52:57,309 - web - ERROR - Error getting workout summary: 'WorkoutManager' object has no attribute 'get_workout_summary_metrics'
2025-05-03 12:52:58,009 - web - ERROR - Error getting workout summary: 'WorkoutManager' object has no attribute 'get_workout_summary_metrics'
2025-05-03 12:52:59,308 - web - ERROR - Error getting workout summary: 'WorkoutManager' object has no attribute 'get_workout_summary_metrics'
2025-05-03 12:52:59,996 - web - ERROR - Error getting workout summary: 'WorkoutManager' object has no attribute 'get_workout_summary_metrics'
2025-05-03 12:53:01,303 - web - ERROR - Error getting workout summary: 'WorkoutManager' object has no attribute 'get_workout_summary_metrics'
2025-05-03 12:53:02,000 - web - ERROR - Error getting workout summary: 'WorkoutManager' object has no attribute 'get_workout_summary_metrics'
2025-05-03 12:53:03,307 - web - ERROR - Error getting workout summary: 'WorkoutManager' object has no attribute 'get_workout_summary_metrics'
2025-05-03 12:53:04,001 - web - ERROR - Error getting workout summary: 'WorkoutManager' object has no attribute 'get_workout_summary_metrics'
2025-05-03 12:53:33,017 - web - ERROR - Error getting workout summary: 'WorkoutManager' object has no attribute 'get_workout_summary_metrics'
2025-05-03 12:53:33,021 - web - ERROR - Error getting workout summary: 'WorkoutManager' object has no attribute 'get_workout_summary_metrics'
2025-05-03 12:53:34,026 - web - ERROR - Error getting workout summary: 'WorkoutManager' object has no attribute 'get_workout_summary_metrics'
2025-05-03 12:53:34,705 - web - ERROR - Error getting workout summary: 'WorkoutManager' object has no attribute 'get_workout_summary_metrics'
2025-05-03 12:53:36,015 - web - ERROR - Error getting workout summary: 'WorkoutManager' object has no attribute 'get_workout_summary_metrics'
2025-05-03 12:53:36,707 - web - ERROR - Error getting workout summary: 'WorkoutManager' object has no attribute 'get_workout_summary_metrics'
2025-05-03 12:53:38,021 - web - ERROR - Error getting workout summary: 'WorkoutManager' object has no attribute 'get_workout_summary_metrics'
2025-05-03 12:53:38,718 - web - ERROR - Error getting workout summary: 'WorkoutManager' object has no attribute 'get_workout_summary_metrics'
2025-05-03 12:53:40,022 - web - ERROR - Error getting workout summary: 'WorkoutManager' object has no attribute 'get_workout_summary_metrics'
2025-05-03 12:53:40,717 - web - ERROR - Error getting workout summary: 'WorkoutManager' object has no attribute 'get_workout_summary_metrics'
2025-05-03 12:53:42,019 - web - ERROR - Error getting workout summary: 'WorkoutManager' object has no attribute 'get_workout_summary_metrics'
2025-05-03 12:53:42,716 - web - ERROR - Error getting workout summary: 'WorkoutManager' object has no attribute 'get_workout_summary_metrics'
2025-05-03 12:53:44,017 - web - ERROR - Error getting workout summary: 'WorkoutManager' object has no attribute 'get_workout_summary_metrics'
2025-05-03 12:53:44,713 - web - ERROR - Error getting workout summary: 'WorkoutManager' object has no attribute 'get_workout_summary_metrics'
2025-05-03 12:58:40,077 - web - ERROR - FIT conversion returned None for workout 1
2025-05-03 13:06:45,970 - web - ERROR - FIT conversion returned None for workout 2
2025-05-03 14:07:40,024 - web - ERROR - FIT conversion returned None for workout 1
2025-05-03 14:07:43,096 - web - ERROR - FIT conversion returned None for workout 2
2025-05-03 14:07:48,060 - web - ERROR - FIT conversion returned None for workout 1
2025-05-03 14:46:25,155 - database - ERROR - Error adding workout data: SQLite objects created in a thread can only be used in that same thread. The object was created in thread id 58136 and this is thread id 78304.
2025-05-03 14:46:25,157 - ftms_connector - ERROR - Error processing indoor bike data: SQLite objects created in a thread can only be used in that same thread. The object was created in thread id 58136 and this is thread id 78304.. Data object: IndoorBikeData(instant_speed=19.14, average_speed=1.16, instant_cadence=32.0, average_cadence=31.0, total_distance=225, resistance_level=None, instant_power=49, average_power=45, total_energy=1, energy_per_hour=0, energy_per_minute=0, heart_rate=102, metabolic_equivalent=None, elapsed_time=44, remaining_time=None)
Traceback (most recent call last):
  File "C:\Users\dougl\rogue_garmin_bridge\src\ftms\ftms_connector.py", line 423, in _handle_indoor_bike_data
    callback(processed_data)
  File "C:\Users\dougl\rogue_garmin_bridge\src\ftms\ftms_manager.py", line 83, in _handle_data
    self._notify_data_callbacks(data)
  File "C:\Users\dougl\rogue_garmin_bridge\src\ftms\ftms_manager.py", line 90, in _notify_data_callbacks
    self._handle_ftms_data(data)
  File "C:\Users\dougl\rogue_garmin_bridge\src\ftms\ftms_manager.py", line 299, in _handle_ftms_data
    self.workout_manager.add_data_point(data)
  File "C:\Users\dougl\rogue_garmin_bridge\src\data\workout_manager.py", line 245, in add_data_point
    success = self.database.add_workout_data(
              ^^^^^^^^^^^^^^^^^^^^^^^^^^^^^^^
  File "C:\Users\dougl\rogue_garmin_bridge\src\data\database.py", line 343, in add_workout_data
    self._disconnect()
  File "C:\Users\dougl\rogue_garmin_bridge\src\data\database.py", line 61, in _disconnect
    self.conn.close()
sqlite3.ProgrammingError: SQLite objects created in a thread can only be used in that same thread. The object was created in thread id 58136 and this is thread id 78304.
2025-05-03 14:46:30,642 - database - ERROR - Error ending workout: database is locked
2025-05-03 14:46:30,645 - web - ERROR - Error ending workout: SQLite objects created in a thread can only be used in that same thread. The object was created in thread id 78304 and this is thread id 58136.
2025-05-03 14:46:31,679 - database - ERROR - Error adding workout data: database is locked
2025-05-03 14:46:31,680 - workout_manager - ERROR - Failed to add data point to workout 5
2025-05-03 14:46:37,165 - database - ERROR - Error adding workout data: database is locked
2025-05-03 14:46:37,166 - workout_manager - ERROR - Failed to add data point to workout 5
2025-05-03 14:46:39,003 - web - ERROR - Error ending workout: 'NoneType' object has no attribute 'commit'
2025-05-03 14:46:42,674 - database - ERROR - Error adding workout data: database is locked
2025-05-03 14:46:42,678 - ftms_connector - ERROR - Error processing indoor bike data: SQLite objects created in a thread can only be used in that same thread. The object was created in thread id 67368 and this is thread id 78304.. Data object: IndoorBikeData(instant_speed=13.67, average_speed=1.11, instant_cadence=23.0, average_cadence=30.0, total_distance=225, resistance_level=None, instant_power=23, average_power=41, total_energy=1, energy_per_hour=0, energy_per_minute=0, heart_rate=103, metabolic_equivalent=None, elapsed_time=47, remaining_time=None)
Traceback (most recent call last):
  File "C:\Users\dougl\rogue_garmin_bridge\src\ftms\ftms_connector.py", line 423, in _handle_indoor_bike_data
    callback(processed_data)
  File "C:\Users\dougl\rogue_garmin_bridge\src\ftms\ftms_manager.py", line 83, in _handle_data
    self._notify_data_callbacks(data)
  File "C:\Users\dougl\rogue_garmin_bridge\src\ftms\ftms_manager.py", line 90, in _notify_data_callbacks
    self._handle_ftms_data(data)
  File "C:\Users\dougl\rogue_garmin_bridge\src\ftms\ftms_manager.py", line 299, in _handle_ftms_data
    self.workout_manager.add_data_point(data)
  File "C:\Users\dougl\rogue_garmin_bridge\src\data\workout_manager.py", line 245, in add_data_point
    success = self.database.add_workout_data(
              ^^^^^^^^^^^^^^^^^^^^^^^^^^^^^^^
  File "C:\Users\dougl\rogue_garmin_bridge\src\data\database.py", line 343, in add_workout_data
    self._disconnect()
  File "C:\Users\dougl\rogue_garmin_bridge\src\data\database.py", line 61, in _disconnect
    self.conn.close()
sqlite3.ProgrammingError: SQLite objects created in a thread can only be used in that same thread. The object was created in thread id 67368 and this is thread id 78304.
2025-05-03 14:55:07,171 - ftms_connector - ERROR - Error processing indoor bike data: SQLite objects created in a thread can only be used in that same thread. The object was created in thread id 80228 and this is thread id 10540.. Data object: IndoorBikeData(instant_speed=10.13, average_speed=0.62, instant_cadence=17.0, average_cadence=16.0, total_distance=0, resistance_level=None, instant_power=13, average_power=12, total_energy=0, energy_per_hour=0, energy_per_minute=0, heart_rate=84, metabolic_equivalent=None, elapsed_time=5, remaining_time=None)
Traceback (most recent call last):
  File "C:\Users\dougl\rogue_garmin_bridge\src\ftms\ftms_connector.py", line 423, in _handle_indoor_bike_data
    callback(processed_data)
  File "C:\Users\dougl\rogue_garmin_bridge\src\ftms\ftms_manager.py", line 83, in _handle_data
    self._notify_data_callbacks(data)
  File "C:\Users\dougl\rogue_garmin_bridge\src\ftms\ftms_manager.py", line 90, in _notify_data_callbacks
    self._handle_ftms_data(data)
  File "C:\Users\dougl\rogue_garmin_bridge\src\ftms\ftms_manager.py", line 299, in _handle_ftms_data
    self.workout_manager.add_data_point(data)
  File "C:\Users\dougl\rogue_garmin_bridge\src\data\workout_manager.py", line 245, in add_data_point
    success = self.database.add_workout_data(
              ^^^^^^^^^^^^^^^^^^^^^^^^^^^^^^^
  File "C:\Users\dougl\rogue_garmin_bridge\src\data\database.py", line 343, in add_workout_data
    self._disconnect()
  File "C:\Users\dougl\rogue_garmin_bridge\src\data\database.py", line 61, in _disconnect
    self.conn.close()
sqlite3.ProgrammingError: SQLite objects created in a thread can only be used in that same thread. The object was created in thread id 80228 and this is thread id 10540.
2025-05-03 14:55:09,205 - database - ERROR - Error adding workout data: SQLite objects created in a thread can only be used in that same thread. The object was created in thread id 62092 and this is thread id 10540.
2025-05-03 14:55:09,215 - workout_manager - ERROR - Failed to add data point to workout 7
2025-05-03 14:55:15,601 - database - ERROR - Error adding workout data: database is locked
2025-05-03 14:55:15,602 - workout_manager - ERROR - Failed to add data point to workout 7
2025-05-03 14:55:19,199 - ftms_connector - ERROR - AttributeError processing indoor bike data: 'NoneType' object has no attribute 'commit'. Data object: IndoorBikeData(instant_speed=10.78, average_speed=0.67, instant_cadence=18.0, average_cadence=18.0, total_distance=16, resistance_level=None, instant_power=14, average_power=14, total_energy=0, energy_per_hour=0, energy_per_minute=0, heart_rate=85, metabolic_equivalent=None, elapsed_time=9, remaining_time=None)
Traceback (most recent call last):
  File "C:\Users\dougl\rogue_garmin_bridge\src\ftms\ftms_connector.py", line 423, in _handle_indoor_bike_data
    callback(processed_data)
  File "C:\Users\dougl\rogue_garmin_bridge\src\ftms\ftms_manager.py", line 83, in _handle_data
    self._notify_data_callbacks(data)
  File "C:\Users\dougl\rogue_garmin_bridge\src\ftms\ftms_manager.py", line 90, in _notify_data_callbacks
    self._handle_ftms_data(data)
  File "C:\Users\dougl\rogue_garmin_bridge\src\ftms\ftms_manager.py", line 299, in _handle_ftms_data
    self.workout_manager.add_data_point(data)
  File "C:\Users\dougl\rogue_garmin_bridge\src\data\workout_manager.py", line 245, in add_data_point
    success = self.database.add_workout_data(
              ^^^^^^^^^^^^^^^^^^^^^^^^^^^^^^^
  File "C:\Users\dougl\rogue_garmin_bridge\src\data\database.py", line 337, in add_workout_data
    self.conn.commit()
    ^^^^^^^^^^^^^^^^
AttributeError: 'NoneType' object has no attribute 'commit'
2025-05-03 14:55:24,740 - database - ERROR - Error adding workout data: database is locked
2025-05-03 14:55:24,741 - workout_manager - ERROR - Failed to add data point to workout 7
2025-05-03 14:55:30,250 - database - ERROR - Error adding workout data: database is locked
2025-05-03 14:55:30,251 - workout_manager - ERROR - Failed to add data point to workout 7
2025-05-03 14:55:35,760 - database - ERROR - Error adding workout data: database is locked
2025-05-03 14:55:35,762 - workout_manager - ERROR - Failed to add data point to workout 7
2025-05-03 14:55:41,265 - database - ERROR - Error adding workout data: database is locked
2025-05-03 14:55:41,266 - workout_manager - ERROR - Failed to add data point to workout 7
2025-05-03 14:55:46,751 - database - ERROR - Error adding workout data: database is locked
2025-05-03 14:55:46,752 - workout_manager - ERROR - Failed to add data point to workout 7
2025-05-03 14:55:52,259 - database - ERROR - Error adding workout data: database is locked
2025-05-03 14:55:52,259 - workout_manager - ERROR - Failed to add data point to workout 7
2025-05-03 14:55:57,778 - database - ERROR - Error adding workout data: database is locked
2025-05-03 14:55:57,779 - workout_manager - ERROR - Failed to add data point to workout 7
2025-05-03 14:56:03,298 - database - ERROR - Error adding workout data: database is locked
2025-05-03 14:56:03,301 - workout_manager - ERROR - Failed to add data point to workout 7
2025-05-03 14:56:08,772 - database - ERROR - Error adding workout data: database is locked
2025-05-03 14:56:08,772 - workout_manager - ERROR - Failed to add data point to workout 7
2025-05-03 14:56:14,299 - database - ERROR - Error adding workout data: database is locked
2025-05-03 14:56:14,301 - workout_manager - ERROR - Failed to add data point to workout 7
2025-05-03 14:56:19,267 - ftms_connector - ERROR - AttributeError processing indoor bike data: 'NoneType' object has no attribute 'commit'. Data object: IndoorBikeData(instant_speed=8.84, average_speed=0.58, instant_cadence=15.0, average_cadence=15.0, total_distance=48, resistance_level=None, instant_power=11, average_power=11, total_energy=0, energy_per_hour=0, energy_per_minute=0, heart_rate=85, metabolic_equivalent=None, elapsed_time=20, remaining_time=None)
Traceback (most recent call last):
  File "C:\Users\dougl\rogue_garmin_bridge\src\ftms\ftms_connector.py", line 423, in _handle_indoor_bike_data
    callback(processed_data)
  File "C:\Users\dougl\rogue_garmin_bridge\src\ftms\ftms_manager.py", line 83, in _handle_data
    self._notify_data_callbacks(data)
  File "C:\Users\dougl\rogue_garmin_bridge\src\ftms\ftms_manager.py", line 90, in _notify_data_callbacks
    self._handle_ftms_data(data)
  File "C:\Users\dougl\rogue_garmin_bridge\src\ftms\ftms_manager.py", line 299, in _handle_ftms_data
    self.workout_manager.add_data_point(data)
  File "C:\Users\dougl\rogue_garmin_bridge\src\data\workout_manager.py", line 245, in add_data_point
    success = self.database.add_workout_data(
              ^^^^^^^^^^^^^^^^^^^^^^^^^^^^^^^
  File "C:\Users\dougl\rogue_garmin_bridge\src\data\database.py", line 337, in add_workout_data
    self.conn.commit()
    ^^^^^^^^^^^^^^^^
AttributeError: 'NoneType' object has no attribute 'commit'
2025-05-03 14:56:24,790 - database - ERROR - Error adding workout data: database is locked
2025-05-03 14:56:24,791 - workout_manager - ERROR - Failed to add data point to workout 7
2025-05-03 14:56:30,300 - database - ERROR - Error adding workout data: database is locked
2025-05-03 14:56:30,301 - workout_manager - ERROR - Failed to add data point to workout 7
2025-05-03 14:56:31,355 - database - ERROR - Error adding workout data: SQLite objects created in a thread can only be used in that same thread. The object was created in thread id 47596 and this is thread id 10540.
2025-05-03 14:56:31,356 - ftms_connector - ERROR - Error processing indoor bike data: SQLite objects created in a thread can only be used in that same thread. The object was created in thread id 47596 and this is thread id 10540.. Data object: IndoorBikeData(instant_speed=11.9, average_speed=0.66, instant_cadence=20.0, average_cadence=17.0, total_distance=64, resistance_level=None, instant_power=15, average_power=13, total_energy=0, energy_per_hour=0, energy_per_minute=0, heart_rate=87, metabolic_equivalent=None, elapsed_time=23, remaining_time=None)
Traceback (most recent call last):
  File "C:\Users\dougl\rogue_garmin_bridge\src\ftms\ftms_connector.py", line 423, in _handle_indoor_bike_data
    callback(processed_data)
  File "C:\Users\dougl\rogue_garmin_bridge\src\ftms\ftms_manager.py", line 83, in _handle_data
    self._notify_data_callbacks(data)
  File "C:\Users\dougl\rogue_garmin_bridge\src\ftms\ftms_manager.py", line 90, in _notify_data_callbacks
    self._handle_ftms_data(data)
  File "C:\Users\dougl\rogue_garmin_bridge\src\ftms\ftms_manager.py", line 299, in _handle_ftms_data
    self.workout_manager.add_data_point(data)
  File "C:\Users\dougl\rogue_garmin_bridge\src\data\workout_manager.py", line 245, in add_data_point
    success = self.database.add_workout_data(
              ^^^^^^^^^^^^^^^^^^^^^^^^^^^^^^^
  File "C:\Users\dougl\rogue_garmin_bridge\src\data\database.py", line 343, in add_workout_data
    self._disconnect()
  File "C:\Users\dougl\rogue_garmin_bridge\src\data\database.py", line 61, in _disconnect
    self.conn.close()
sqlite3.ProgrammingError: SQLite objects created in a thread can only be used in that same thread. The object was created in thread id 47596 and this is thread id 10540.
2025-05-03 14:56:36,416 - database - ERROR - Error ending workout: database is locked
2025-05-03 14:56:36,418 - workout_manager - ERROR - Failed to end workout 7
2025-05-03 14:56:36,835 - database - ERROR - Error adding workout data: database is locked
2025-05-03 14:56:36,835 - workout_manager - ERROR - Failed to add data point to workout 7
2025-05-03 14:56:42,318 - database - ERROR - Error adding workout data: database is locked
2025-05-03 14:56:42,319 - workout_manager - ERROR - Failed to add data point to workout 7
2025-05-03 14:56:43,481 - database - ERROR - Error ending workout: SQLite objects created in a thread can only be used in that same thread. The object was created in thread id 75228 and this is thread id 67312.
2025-05-03 14:56:43,483 - workout_manager - ERROR - Failed to end workout 7
2025-05-03 14:56:47,836 - database - ERROR - Error adding workout data: database is locked
2025-05-03 14:56:47,838 - workout_manager - ERROR - Failed to add data point to workout 7
